Workbook

Sheet Faktor
A1: Forøgelses faktor
A3: 2015 | B3: 0.014
A4: 2016 | B4: 0.019
A5: 2017 | B5: 0.014
A6: 2018 | B6: 0.019
A7: 2019 | B7: 0.018
A8: 2020 | B8: 0.021
A9: 2021 | B9: 0.021
A10: 2022 | B10: 0.021

Sheet Ark2

Sheet 2014
E1: Bosta
A2: Sted | E2: Dato
A3: Opgave | E3: Mont.
A4: Kunde | E4: Demo.
A5: Sag nr. | E5: Montør
B6: Pris | C6: Antal | D6: I alt | F6: Pris | G6: Antal | H6: I alt
A7: Spindelfod kort | B7: 2.06 | E7: Tværprofil aludr. | F7: 3.52
A8: Spindelfod lang | B8: 2.06 | E8: Alu. Drager pr. m. | F8: 13.2
A9: Vippefod | B9: 3.41 | E9: Gelændertvinge | F9: 3.08
A10: Strø / trykudligner | B10: 1.37 | E10: Tværprofin ram. | F10: 11.69
A11: Ramme 200/70 | B11: 14.35 | E11: Dæklås | F11: 3.96
A12: Ramme 150/70 | B12: 14.35 | E12: Samlerør til aludr. | F12: 10.31
A13: Ramme 100/70 | B13: 14.35 | E13: Flapper/Singel | F13: 3.08
A14: Ramme 80/70 | B14: 14.35 | E14: Fastkobling | F14: 3.08
A15: Ramme 66/70 | B15: 14.35 | E15: Drejekobling | F15: 3.08
A16: Ramme Kat. 2 tillæg | B16: 2.12 | E16: Kipfingerkobling | F16: 3.08
A17: Gulvplade 300/70 | B17: 4.91 | E17: SK Kobling | F17: 3.08
A18: Gulvplade 250/70 | B18: 4.91 | E18: Rørsamler | F18: 3.08
A19: Gulvplade 200/70 | B19: 4.91 | E19: Stilladsrør 1 M | F19: 4.25
A20: Gulvplade 150/70 | B20: 4.91 | E20: Stilladsrør 2 M | F20: =F19*2 -> 8.5
A21: Gulvplade 125/70 | B21: 4.91 | E21: Stilladsrør 3 M | F21: =F19*3 -> 12.75
A22: Gulvplade 70/70 | B22: 4.91 | E22: Stilladsrør 4 M | F22: =F19*4 -> 17
A23: Gulvplade 300/35 | B23: 3.69 | E23: Stilladsrør 5 M | F23: =F19*5 -> 21.25
A24: Gulvplade 250/35 | B24: 3.69 | E24: Stilladsrør 6 M | F24: =F19*6 -> 25.5
A25: Gulvplade 200/35 | B25: 3.69 | E25: Alu.bro pr. m | F25: 11.66
A26: Gulvplade 125/35 | B26: 3.69 | E26: Reklameskilt | F26: 7.98
A27: Stigedæk 300/70 | B27: 7.78 | E27: Grøn skilt | F27: 0
A28: Stigedæk 250/70 | B28: 7.78 | E28: Startprofil til trappe | F28: 3.19
A29: Udkrag.70 tillæg | B29: 4.91 | E29: Alu trappeløb | F29: 39.6
A30: Udkrag.35 tillæg | B30: 3.68 | E30: Gelænder trpl | F30: 9.9
A31: Stige 200 | B31: 3.49 | E31: Ramme 200/100 | F31: 19.48
A32: Stige 300 | B32: 3.49 | E32: Tværgel. 100 | F32: 2.65
A33: Stigestøtte | B33: 2.22 | E33: Dobb. Gel. St. 100 | F33: 7.33
A34: Diagonaler 200 | B34: 5.61 | E34: Gelænderst. 100 | F34: 7.33
A35: Diagonaler 203 | B35: 5.61 | E35: Dobb bundramme | F35: 34.6
A36: Gelænder 125 | B36: 2.4 | E36: Tragt | F36: 30.08
A37: Gelænder 150 | B37: 2.4 | E37: Skaktrør | F37: 30.08
A38: Gelænder 200 | B38: 2.4
A39: Gelænder 250 | B39: 2.4 | E39: Net pr kvm | F39: 2.2
A40: Gelænder 300 | B40: 2.4 | E40: Plast pr kvm | F40: 5.28
...

Sheet 2015
E1: Bosta
A2: Sted | E2: Dato
A3: Opgave | E3: Mont.
A4: Kunde | E4: Demo.
A5: Sag nr. | E5: Montør
B6: Pris | C6: Antal | D6: I alt | F6: Pris | G6: Antal | H6: I alt
A7: Spindelfod kort | B7: =('2014'!B7*Faktor!$B$3)+'2014'!B7 -> 2.08884 | E7: Tværprofil aludr. | F7: =('2014'!F7*Faktor!$B$3)+'2014'!F7 -> 3.56928
A8: Spindelfod lang | B8: =('2014'!B8*Faktor!$B$3)+'2014'!B8 -> 2.08884 | E8: Alu. Drager pr. m. | F8: =('2014'!F8*Faktor!$B$3)+'2014'!F8 -> 13.3848
A9: Vippefod | B9: =('2014'!B9*Faktor!$B$3)+'2014'!B9 -> 3.45774 | E9: Gelændertvinge | F9: =('2014'!F9*Faktor!$B$3)+'2014'!F9 -> 3.12312
A10: Strø / trykudligner | B10: =('2014'!B10*Faktor!$B$3)+'2014'!B10 -> 1.38918 | E10: Tværprofin ram. | F10: =('2014'!F10*Faktor!$B$3)+'2014'!F10 -> 11.85366
A11: Ramme 200/70 | B11: =('2014'!B11*Faktor!$B$3)+'2014'!B11 -> 14.5509 | E11: Dæklås | F11: =('2014'!F11*Faktor!$B$3)+'2014'!F11 -> 4.01544
A12: Ramme 150/70 | B12: =('2014'!B12*Faktor!$B$3)+'2014'!B12 -> 14.5509 | E12: Samlerør til aludr. | F12: =('2014'!F12*Faktor!$B$3)+'2014'!F12 -> 10.45434
A13: Ramme 100/70 | B13: =('2014'!B13*Faktor!$B$3)+'2014'!B13 -> 14.5509 | E13: Flapper/Singel | F13: =('2014'!F13*Faktor!$B$3)+'2014'!F13 -> 3.12312
A14: Ramme 80/70 | B14: =('2014'!B14*Faktor!$B$3)+'2014'!B14 -> 14.5509 | E14: Fastkobling | F14: =('2014'!F14*Faktor!$B$3)+'2014'!F14 -> 3.12312
A15: Ramme 66/70 | B15: =('2014'!B15*Faktor!$B$3)+'2014'!B15 -> 14.5509 | E15: Drejekobling | F15: =('2014'!F15*Faktor!$B$3)+'2014'!F15 -> 3.12312
A16: Ramme Kat. 2 tillæg | B16: =('2014'!B16*Faktor!$B$3)+'2014'!B16 -> 2.14968 | E16: Kipfingerkobling | F16: =('2014'!F16*Faktor!$B$3)+'2014'!F16 -> 3.12312
A17: Gulvplade 300/70 | B17: =('2014'!B17*Faktor!$B$3)+'2014'!B17 -> 4.97874 | E17: SK Kobling | F17: =('2014'!F17*Faktor!$B$3)+'2014'!F17 -> 3.12312
A18: Gulvplade 250/70 | B18: =('2014'!B18*Faktor!$B$3)+'2014'!B18 -> 4.97874 | E18: Rørsamler | F18: =('2014'!F18*Faktor!$B$3)+'2014'!F18 -> 3.12312
... A25: Gulvplade 200/35 | B25: =('2014'!B25*Faktor!$B$3)+'2014'!B25 -> 3.74166 | E25: Alu.bro pr. m | F25: =('2014'!F25*Faktor!$B$3)+'2014'!F25 -> 11.82324
A26: Gulvplade 125/35 | B26: =('2014'!B26*Faktor!$B$3)+'2014'!B26 -> 3.74166 | E26: Reklameskilt | F26: ='2014'!F26 -> 7.98
A27: Stigedæk 300/70 | B27: =('2014'!B27*Faktor!$B$3)+'2014'!B27 -> 7.88892 | E27: Grøn skilt | F27: =('2014'!F27*Faktor!$B$3)+'2014'!F27 -> 0
A28: Stigedæk 250/70 | B28: =('2014'!B28*Faktor!$B$3)+'2014'!B28 -> 7.88892 | E28: Startprofil til trappe | F28: =('2014'!F28*Faktor!$B$3)+'2014'!F28 -> 3.23466
A29: Udkrag.70 tillæg | B29: =('2014'!B29*Faktor!$B$3)+'2014'!B29 -> 4.97874 | E29: Alu trappeløb | F29: =('2014'!F29*Faktor!$B$3)+'2014'!F29 -> 40.1544
A30: Udkrag.35 tillæg | B30: =('2014'!B30*Faktor!$B$3)+'2014'!B30 -> 3.73152 | E30: Gelænder trpl | F30: =('2014'!F30*Faktor!$B$3)+'2014'!F30 -> 10.0386
A31: Stige 200 | B31: =('2014'!B31*Faktor!$B$3)+'2014'!B31 -> 3.53886 | E31: Ramme 200/100 | F31: =('2014'!F31*Faktor!$B$3)+'2014'!F31 -> 19.75272
A32: Stige 300 | B32: =('2014'!B32*Faktor!$B$3)+'2014'!B32 -> 3.53886 | E32: Tværgel. 100 | F32: =('2014'!F32*Faktor!$B$3)+'2014'!F32 -> 2.6871
A33: Stigestøtte | B33: =('2014'!B33*Faktor!$B$3)+'2014'!B33 -> 2.25108 | E33: Dobb. Gel. St. 100 | F33: =('2014'!F33*Faktor!$B$3)+'2014'!F33 -> 7.43262
A34: Diagonaler 200 | B34: =('2014'!B34*Faktor!$B$3)+'2014'!B34 -> 5.68854 | E34: Gelænderst. 100 | F34: =('2014'!F34*Faktor!$B$3)+'2014'!F34 -> 7.43262
A35: Diagonaler 203 | B35: =('2014'!B35*Faktor!$B$3)+'2014'!B35 -> 5.68854 | E35: Dobb bundramme | F35: =('2014'!F35*Faktor!$B$3)+'2014'!F35 -> 35.0844
A36: Gelænder 125 | B36: =('2014'!B36*Faktor!$B$3)+'2014'!B36 -> 2.4336 | E36: Tragt | F36: =('2014'!F36*Faktor!$B$3)+'2014'!F36 -> 30.50112
A37: Gelænder 150 | B37: =('2014'!B37*Faktor!$B$3)+'2014'!B37 -> 2.4336 | E37: Skaktrør | F37: =('2014'!F37*Faktor!$B$3)+'2014'!F37 -> 30.50112
A38: Gelænder 200 | B38: =('2014'!B38*Faktor!$B$3)+'2014'!B38 -> 2.4336
A39: Gelænder 250 | B39: =('2014'!B39*Faktor!$B$3)+'2014'!B39 -> 2.4336 | E39: Net pr kvm | F39: =('2014'!F39*Faktor!$B$3)+'2014'!F39 -> 2.2308
A40: Gelænder 300 | B40: =('2014'!B40*Faktor!$B$3)+'2014'!B40 -> 2.4336 | E40: Plast pr kvm | F40: =('2014'!F40*Faktor!$B$3)+'2014'!F40 -> 5.35392
A41: Tvær Gel. 70 | B41: =('2014'!B41*Faktor!$B$3)+'2014'!B41 -> 2.4336
A42: Dob. Tværgelænder | B42: =('2014'!B42*Faktor!$B$3)+'2014'!B42 -> 4.8672
A43: Dob. G | B43: =('2014'!B43*Faktor!$B$3)+'2014'!B43 -> 14.54076
A44: L Rør | B44: =('2014'!B44*Faktor!$B$3)+'2014'!B44 -> 14.54076
A45: B Rør | B45: =('2014'!B45*Faktor!$B$3)+'2014'!B45 -> 6.29694 | E45: Kirkefod | F45: =('2014'!F45*Faktor!$B$3)+'2014'!F45 -> 5.36406
A46: Konsol 100 | B46: =('2014'!B46*Faktor!$B$3)+'2014'!B46 -> 15.08832 | E46: Plader pr kvm | F46: =('2014'!F46*Faktor!$B$3)+'2014'!F46 -> 6.41862
...

Sheet 2016
E1: Bosta 2016
A2: Sted | E2: Dato
A3: Opgave | E3: Mont.
A4: Kunde | E4: Demo.
A5: Sag nr. | E5: Montør
B6: Pris | C6: Antal | D6: I alt | F6: Pris | G6: Antal | H6: I alt
A7: Spindelfod kort | B7: =('2015'!B7*Faktor!$B$4)+'2015'!B7 -> 2.128528 | E7: Tværprofil aludr. | F7: =('2015'!F7*Faktor!$B$4)+'2015'!F7 -> 3.6370963
A8: Spindelfod lang | B8: =('2015'!B8*Faktor!$B$4)+'2015'!B8 -> 2.128528 | E8: Alu. Drager pr. m. | F8: =('2015'!F8*Faktor!$B$4)+'2015'!F8 -> 13.639111
A9: Vippefod | B9: =('2015'!B9*Faktor!$B$4)+'2015'!B9 -> 3.5234371 | E9: Gelændertvinge | F9: =('2015'!F9*Faktor!$B$4)+'2015'!F9 -> 3.1824593
A10: Strø / trykudligner | B10: =('2015'!B10*Faktor!$B$4)+'2015'!B10 -> 1.4155744 | E10: Tværprofin ram. | F10: =('2015'!F10*Faktor!$B$4)+'2015'!F10 -> 12.07888
A11: Ramme 200/70 | B11: =('2015'!B11*Faktor!$B$4)+'2015'!B11 -> 14.827367 | E11: Dæklås | F11: =('2015'!F11*Faktor!$B$4)+'2015'!F11 -> 4.0917334
A12: Ramme 150/70 | B12: =('2015'!B12*Faktor!$B$4)+'2015'!B12 -> 14.827367 | E12: Samlerør til aludr. | F12: =('2015'!F12*Faktor!$B$4)+'2015'!F12 -> 10.652972
A13: Ramme 100/70 | B13: =('2015'!B13*Faktor!$B$4)+'2015'!B13 -> 14.827367 | E13: Flapper/Singel | F13: =('2015'!F13*Faktor!$B$4)+'2015'!F13 -> 3.1824593
A14: Ramme 80/70 | B14: =('2015'!B14*Faktor!$B$4)+'2015'!B14 -> 14.827367 | E14: Fastkobling | F14: =('2015'!F14*Faktor!$B$4)+'2015'!F14 -> 3.1824593
A15: Ramme 66/70 | B15: =('2015'!B15*Faktor!$B$4)+'2015'!B15 -> 14.827367 | E15: Drejekobling | F15: =('2015'!F15*Faktor!$B$4)+'2015'!F15 -> 3.1824593
A16: Ramme Kat. 2 tillæg | B16: =('2015'!B16*Faktor!$B$4)+'2015'!B16 -> 2.1905239 | E16: Kipfingerkobling | F16: =('2015'!F16*Faktor!$B$4)+'2015'!F16 -> 3.1824593
A17: Gulvplade 300/70 | B17: =('2015'!B17*Faktor!$B$4)+'2015'!B17 -> 5.0733361 | E17: SK Kobling | F17: =('2015'!F17*Faktor!$B$4)+'2015'!F17 -> 3.1824593
A18: Gulvplade 250/70 | B18: =('2015'!B18*Faktor!$B$4)+'2015'!B18 -> 5.0733361 | E18: Rørsamler | F18: =('2015'!F18*Faktor!$B$4)+'2015'!F18 -> 3.1824593
... A24: Gulvplade 250/35 | B24: =('2015'!B24*Faktor!$B$4)+'2015'!B24 -> 3.8127515 | E24: Stilladsrør 6 M | F24: =('2015'!F24*Faktor!$B$4)+'2015'!F24 -> 26.348283
A25: Gulvplade 200/35 | B25: =('2015'!B25*Faktor!$B$4)+'2015'!B25 -> 3.8127515 | E25: Bøjleanker | F25: =('2015'!B49*Faktor!$B$4)+'2015'!B49 -> 6.5405738
A26: Gulvplade 150/35 | B26: 3.81 | E26: Rør Anker | F26: =('2015'!B50*Faktor!$B$4)+'2015'!B50 -> 8.1834667
A27: Gulvplade 125/35 | B27: =('2015'!B26*Faktor!$B$4)+'2015'!B26 -> 3.8127515 | E27: Reklameskilt | F27: =('2015'!F26*Faktor!$B$4)+'2015'!F26 -> 8.13162
A28: Stigedæk 300/70 | B28: =('2015'!B27*Faktor!$B$4)+'2015'!B27 -> 8.0388095 | E28: Grøn skilt | F28: =('2015'!F27*Faktor!$B$4)+'2015'!F27 -> 0
A29: Stigedæk 250/70 | B29: =('2015'!B28*Faktor!$B$4)+'2015'!B28 -> 8.0388095 | E29: Startprofil til trappe | F29: =('2015'!F28*Faktor!$B$4)+'2015'!F28 -> 3.2961185
A30: Udkrag.70 tillæg | B30: =('2015'!B29*Faktor!$B$4)+'2015'!B29 -> 5.0733361 | E30: Alu trappeløb | F30: =('2015'!F29*Faktor!$B$4)+'2015'!F29 -> 40.917334
A31: Udkrag.35 tillæg | B31: =('2015'!B30*Faktor!$B$4)+'2015'!B30 -> 3.8024189 | E31: Gelænder trpl | F31: =('2015'!F30*Faktor!$B$4)+'2015'!F30 -> 10.229333
A32: Stige 200 | B32: =('2015'!B31*Faktor!$B$4)+'2015'!B31 -> 3.6060983 | E32: Ramme 200/100 | F32: =('2015'!F31*Faktor!$B$4)+'2015'!F31 -> 20.128022
A33: Stige 300 | B33: =('2015'!B32*Faktor!$B$4)+'2015'!B32 -> 3.6060983 | E33: Tværgel. 100 | F33: =('2015'!F32*Faktor!$B$4)+'2015'!F32 -> 2.7381549
A34: Stigestøtte | B34: =('2015'!B33*Faktor!$B$4)+'2015'!B33 -> 2.2938505 | E34: Dobb. Gel. St. 100 | F34: =('2015'!F33*Faktor!$B$4)+'2015'!F33 -> 7.5738398
A35: Diagonaler 200 | B35: =('2015'!B34*Faktor!$B$4)+'2015'!B34 -> 5.7966223 | E35: Gelænderst. 100 | F35: =('2015'!F34*Faktor!$B$4)+'2015'!F34 -> 7.5738398
A36: Diagonaler 203 | B36: =('2015'!B35*Faktor!$B$4)+'2015'!B35 -> 5.7966223 | E36: Dobb bundramme | F36: =('2015'!F35*Faktor!$B$4)+'2015'!F35 -> 35.751004
A37: Gelænder 125 | B37: =('2015'!B36*Faktor!$B$4)+'2015'!B36 -> 2.4798384 | E37: Tragt | F37: =('2015'!F36*Faktor!$B$4)+'2015'!F36 -> 31.080641
A38: Gelænder 150 | B38: =('2015'!B37*Faktor!$B$4)+'2015'!B37 -> 2.4798384 | E38: Skaktrør | F38: =('2015'!F37*Faktor!$B$4)+'2015'!F37 -> 31.080641
A39: Gelænder 200 | B39: =('2015'!B38*Faktor!$B$4)+'2015'!B38 -> 2.4798384 | E39: Alu.bro pr. m | F39: =('2015'!F25*Faktor!$B$4)+'2015'!F25 -> 12.047882
A40: Gelænder 250 | B40: =('2015'!B39*Faktor!$B$4)+'2015'!B39 -> 2.4798384 | E40: Net pr kvm | F40: =('2015'!F39*Faktor!$B$4)+'2015'!F39 -> 2.2731852
A41: Gelænder 300 | B41: =('2015'!B40*Faktor!$B$4)+'2015'!B40 -> 2.4798384 | E41: Plast pr kvm | F41: =('2015'!F40*Faktor!$B$4)+'2015'!F40 -> 5.4556445
A42: Tvær Gel. 70 | B42: =('2015'!B41*Faktor!$B$4)+'2015'!B41 -> 2.4798384
A43: Dob. Tværgelænder | B43: =('2015'!B42*Faktor!$B$4)+'2015'!B42 -> 4.9596768 | E43: Geda hejs | F43: 238.26
A44: Dob. G | B44: =('2015'!B43*Faktor!$B$4)+'2015'!B43 -> 14.817034 | E44: El hejs | F44: 120.32
A45: L Rør | B45: =('2015'!B44*Faktor!$B$4)+'2015'!B44 -> 14.817034
...

Sheet 2017
A1: Bosta 2017
A2: Sted | E2: Dato
A3: Opgave | E3: Mont.
A4: Kunde | E4: Demo.
A5: Sag nr. | E5: Montør
B6: Pris | C6: Antal | D6: I alt | F6: Pris | G6: Antal | H6: I alt
A7: Spindelfod kort | B7: 2.17 | E7: Tværprofil aludr. | F7: 12.3
A8: Spindelfod lang | B8: 2.17 | E8: Alu. Drager pr. m. | F8: 13.88
A9: Vippefod | B9: 3.59 | E9: Gelændertvinge | F9: 3.24
A10: Strø / trykudligner | B10: =('2015'!B10*Faktor!$B$5)+'2016'!B10 -> 1.4350229 | E10: Tværprofin ram. | F10: 12.3
A11: Ramme 200/70 | B11: 15.09 | E11: Dæklås | F11: 3.24
A12: Ramme 150/70 | B12: 15.09 | E12: Samlerør til aludr. | F12: 11.57
A13: Ramme 100/70 | B13: 15.09 | E13: Flapper/Singel | F13: 3.24
A14: Ramme 80/70 | B14: 15.09 | E14: Fastkobling | F14: 3.24
A15: Ramme 66/70 | B15: 15.09 | E15: Drejekobling | F15: 3.24
A16: Ramme Kat. 2 tillæg | B16: 2.24 | E16: Kipfingerkobling | F16: 3.24
A17: Gulvplade 300/70 | B17: 5.16 | E17: SK Kobling | F17: 3.24
A18: Gulvplade 250/70 | B18: 5.16 | E18: Rørsamler | F18: 3.24
A19: Gulvplade 200/70 | B19: 5.16 | E19: Stilladsrør 1 M | F19: 4.47
A20: Gulvplade 150/70 | B20: 5.16 | E20: Stilladsrør 2 M | F20: 8.94
A21: Gulvplade 125/70 | B21: 5.16 | E21: Stilladsrør 3 M | F21: 13.41
A22: Gulvplade 70/70 | B22: 5.16 | E22: Stilladsrør 4 M | F22: 17.88
... A26: Gulvplade 150/35 | B26: 3.88 | E26: Rør Anker | F26: 8.33
A27: Gulvplade 125/35 | B27: 3.88 | E27: Reklameskilt | F27: =('2016'!F27*Faktor!$B$5)+'2016'!F27 -> 8.2454627
A28: Stigedæk 300/70 | B28: 8.18 | E28: Grønne skilte | F28: 5
A29: Stigedæk 250/70 | B29: 8.18 | E29: Startprofil til trappe | F29: 3.35
A30: Stigedæk 200/70 | B30: 8.18 | E30: Alu trappeløb | F30: 41.65
A31: Udkrag.70 tillæg | B31: 5.16 | E31: Gelænder trpl | F31: 10.42
A32: Udkrag.35 tillæg | B32: 3.88 | E32: Ramme 200/100 | F32: =('2016'!F32*Faktor!$B$5)+'2016'!F32 -> 20.409814
A33: Stige 200 | B33: 3.67 | E33: Tværgel. 100 | F33: =('2016'!F33*Faktor!$B$5)+'2016'!F33 -> 2.7764891
A34: Stige 300 | B34: 3.67 | E34: Dobb. Gel. St. 100 | F34: =('2016'!F34*Faktor!$B$5)+'2016'!F34 -> 7.6798735
A35: Stigestøtte | B35: =('2015'!B34*Faktor!$B$5)+'2016'!B34 -> 2.3734901 | E35: Gelænderst. 100 | F35: =('2016'!F35*Faktor!$B$5)+'2016'!F35 -> 7.6798735
A36: Diagonaler 200 | B36: 5.9 | E36: Dobb bundramme | F36: 36.4
A37: Diagonaler 203 | B37: 5.9 | E37: Tragt | F37: 31.64
A38: Gelænder 125 | B38: 2.53 | E38: Skaktrør | F38: 31.64
A39: Gelænder 150 | B39: 2.53 | E39: Alu.bro pr. m | F39: 12.26
A40: Gelænder 200 | B40: 2.53 | E40: Net pr kvm | F40: 2.31
A41: Gelænder 250 | B41: 2.53 | E41: Plast pr kvm | F41: 5.56
A42: Gelænder 300 | B42: 2.53 | E42: Blindrum | F42: 5.16
A43: Tvær Gel. 70 | B43: 2.53 | E43: Geda hejs | F43: 245.93
...

Sheet 2018
E1: Bosta 2018
A2: Sted | E2: Dato
A3: Opgave | E3: Mont.
A4: Kunde | E4: Demo.
A5: Sag nr. | E5: Montør
B6: Pris | C6: Antal | D6: I alt | F6: Pris | G6: Antal | H6: I alt
A7: Spindelfod kort | B7: =('2017'!B7*Faktor!$B$6)+'2017'!B7 -> 2.21123 | E7: Tværprofil aludr. | F7: =('2017'!F7*Faktor!$B$6)+'2017'!F7 -> 12.5337
A8: Spindelfod lang | B8: =('2017'!B8*Faktor!$B$6)+'2017'!B8 -> 2.21123 | E8: Alu. Drager pr. m. | F8: =('2017'!F8*Faktor!$B$6)+'2017'!F8 -> 14.14372
A9: Vippefod | B9: =('2017'!B9*Faktor!$B$6)+'2017'!B9 -> 3.65821 | E9: Gelændertvinge | F9: =('2017'!F9*Faktor!$B$6)+'2017'!F9 -> 3.30156
A10: Strø / trykudligner | B10: 1.47 | E10: Tværprofin ram. | F10: =('2017'!F10*Faktor!$B$6)+'2017'!F10 -> 12.5337
A11: Ramme 200/70 | B11: =('2017'!B11*Faktor!$B$6)+'2017'!B11 -> 15.37671 | E11: Dæklås | F11: =('2017'!F11*Faktor!$B$6)+'2017'!F11 -> 3.30156
A12: Ramme 150/70 | B12: =('2017'!B12*Faktor!$B$6)+'2017'!B12 -> 15.37671 | E12: Samlerør til aludr. | F12: =('2017'!F12*Faktor!$B$6)+'2017'!F12 -> 11.78983
A13: Ramme 100/70 | B13: =('2017'!B13*Faktor!$B$6)+'2017'!B13 -> 15.37671 | E13: Flapper/Singel | F13: =('2017'!F13*Faktor!$B$6)+'2017'!F13 -> 3.30156
A14: Ramme 80/70 | B14: =('2017'!B14*Faktor!$B$6)+'2017'!B14 -> 15.37671 | E14: Fastkobling | F14: =('2017'!F14*Faktor!$B$6)+'2017'!F14 -> 3.30156
A15: Ramme 66/70 | B15: =('2017'!B15*Faktor!$B$6)+'2017'!B15 -> 15.37671 | E15: Drejekobling | F15: =('2017'!F15*Faktor!$B$6)+'2017'!F15 -> 3.30156
A16: Ramme Kat. 2 tillæg | B16: =('2017'!B16*Faktor!$B$6)+'2017'!B16 -> 2.28256 | E16: Kipfingerkobling | F16: =('2017'!F16*Faktor!$B$6)+'2017'!F16 -> 3.30156
A17: Gulvplade 300/70 | B17: =('2017'!B17*Faktor!$B$6)+'2017'!B17 -> 5.25804 | E17: SK Kobling | F17: =('2017'!F17*Faktor!$B$6)+'2017'!F17 -> 3.30156
A18: Gulvplade 250/70 | B18: =('2017'!B18*Faktor!$B$6)+'2017'!B18 -> 5.25804 | E18: Rørsamler | F18: =('2017'!F18*Faktor!$B$6)+'2017'!F18 -> 3.30156
A19: Gulvplade 200/70 | B19: =('2017'!B19*Faktor!$B$6)+'2017'!B19 -> 5.25804 | E19: Stilladsrør 1 M | F19: =('2017'!F19*Faktor!$B$6)+'2017'!F19 -> 4.55493
A20: Gulvplade 150/70 | B20: =('2017'!B20*Faktor!$B$6)+'2017'!B20 -> 5.25804 | E20: Stilladsrør 2 M | F20: =('2017'!F20*Faktor!$B$6)+'2017'!F20 -> 9.10986
A21: Gulvplade 125/70 | B21: =('2017'!B21*Faktor!$B$6)+'2017'!B21 -> 5.25804 | E21: Stilladsrør 3 M | F21: =('2017'!F21*Faktor!$B$6)+'2017'!F21 -> 13.66479
A22: Gulvplade 70/70 | B22: =('2017'!B22*Faktor!$B$6)+'2017'!B22 -> 5.25804 | E22: Stilladsrør 4 M | F22: =('2017'!F22*Faktor!$B$6)+'2017'!F22 -> 18.21972
... A26: Gulvplade 150/35 | B26: =('2017'!B26*Faktor!$B$6)+'2017'!B26 -> 3.95372 | E26: Rør Anker | F26: =('2017'!F26*Faktor!$B$6)+'2017'!F26 -> 8.48827
A27: Gulvplade 125/35 | B27: =('2017'!B27*Faktor!$B$6)+'2017'!B27 -> 3.95372 | E27: Reklameskilt | F27: 8.41
A28: Stigedæk 300/70 | B28: =('2017'!B28*Faktor!$B$6)+'2017'!B28 -> 8.33542 | E28: Grøn skilt | F28: 5
A29: Stigedæk 250/70 | B29: =('2017'!B29*Faktor!$B$6)+'2017'!B29 -> 8.33542 | E29: Startprofil til trappe | F29: =('2017'!F29*Faktor!$B$6)+'2017'!F29 -> 3.41365
A30: Stigedæk 200/70 | B30: 8.34 | E30: Alu trappeløb | F30: =('2017'!F30*Faktor!$B$6)+'2017'!F30 -> 42.44135
A31: Udkrag.70 tillæg | B31: =('2017'!B31*Faktor!$B$6)+'2017'!B31 -> 5.25804 | E31: Gelænder trpl | F31: =('2017'!F31*Faktor!$B$6)+'2017'!F31 -> 10.61798
A32: Udkrag.35 tillæg | B32: =('2017'!B32*Faktor!$B$6)+'2017'!B32 -> 3.95372 | E32: Ramme 200/100 | F32: =('2017'!F32*Faktor!$B$6)+'2017'!F32 -> 20.7976
A33: Stige 200 | B33: =('2017'!B33*Faktor!$B$6)+'2017'!B33 -> 3.73973 | E33: Tværgel. 100 | F33: =('2017'!F33*Faktor!$B$6)+'2017'!F33 -> 2.8292424
A34: Stige 300 | B34: =('2017'!B34*Faktor!$B$6)+'2017'!B34 -> 3.73973 | E34: Dobb. Gel. St. 100 | F34: =('2017'!F34*Faktor!$B$6)+'2017'!F34 -> 7.8257911
A35: Stigestøtte | B35: =('2017'!B35*Faktor!$B$6)+'2017'!B35 -> 2.4185864 | E35: Gelænderst. 100 | F35: =('2017'!F35*Faktor!$B$6)+'2017'!F35 -> 7.8257911
A36: Diagonaler 200 | B36: =('2017'!B36*Faktor!$B$6)+'2017'!B36 -> 6.0121 | E36: Dobb bundramme | F36: =('2017'!F36*Faktor!$B$6)+'2017'!F36 -> 37.0916
A37: Diagonaler 203 | B37: =('2017'!B37*Faktor!$B$6)+'2017'!B37 -> 6.0121 | E37: Tragt | F37: =('2017'!F37*Faktor!$B$6)+'2017'!F37 -> 32.24116
A38: Gelænder 125 | B38: =('2017'!B38*Faktor!$B$6)+'2017'!B38 -> 2.57807 | E38: Skaktrør | F38: =('2017'!F38*Faktor!$B$6)+'2017'!F38 -> 32.24116
A39: Gelænder 150 | B39: =('2017'!B39*Faktor!$B$6)+'2017'!B39 -> 2.57807 | E39: Alu.bro pr. m | F39: =('2017'!F39*Faktor!$B$6)+'2017'!F39 -> 12.49294
A40: Gelænder 200 | B40: =('2017'!B40*Faktor!$B$6)+'2017'!B40 -> 2.57807 | E40: Net pr kvm | F40: =('2017'!F40*Faktor!$B$6)+'2017'!F40 -> 2.35389
A41: Gelænder 250 | B41: =('2017'!B41*Faktor!$B$6)+'2017'!B41 -> 2.57807 | E41: Plast pr kvm | F41: =('2017'!F41*Faktor!$B$6)+'2017'!F41 -> 5.66564
A42: Gelænder 300 | B42: =('2017'!B42*Faktor!$B$6)+'2017'!B42 -> 2.57807 | E42: Blindrum | F42: =('2017'!F42*Faktor!$B$6)+'2017'!F42 -> 5.25804
... A44: Dob. Tværgelænder | B44: =('2017'!B44*Faktor!$B$6)+'2017'!B44 -> 5.14595 | E44: El hejs | F44: =('2017'!F44*Faktor!$B$6)+'2017'!F44 -> 126.56999
...

Sheet 2019
E1: Bosta 2019
A2: Sted | E2: Dato
A3: Opgave | E3: Mont.
A4: Kunde | E4: Demo.
A5: Sag nr. | E5: Montør
B6: Pris | C6: Antal | D6: I alt | F6: Pris | G6: Antal | H6: I alt
A7: Spindelfod kort | B7: =('2018'!B7*Faktor!$B$7)+'2018'!B7 -> 2.2510321 | E7: Tværprofil aludr. | F7: =('2018'!F7*Faktor!$B$7)+'2018'!F7 -> 12.759307
A8: Spindelfod lang | B8: =('2018'!B8*Faktor!$B$7)+'2018'!B8 -> 2.2510321 | E8: Alu. Drager pr. m. | F8: =('2018'!F8*Faktor!$B$7)+'2018'!F8 -> 14.398307
A9: Vippefod | B9: =('2018'!B9*Faktor!$B$7)+'2018'!B9 -> 3.7240578 | E9: Gelændertvinge | F9: =('2018'!F9*Faktor!$B$7)+'2018'!F9 -> 3.3609881
A10: Strø / trykudligner | B10: =('2018'!B10*Faktor!$B$7)+'2018'!B10 -> 1.49646 | E10: Tværprofin ram. | F10: =('2018'!F10*Faktor!$B$7)+'2018'!F10 -> 12.759307
A11: Ramme 200/70 | B11: =('2018'!B11*Faktor!$B$7)+'2018'!B11 -> 15.653491 | E11: Dæklås | F11: =('2018'!F11*Faktor!$B$7)+'2018'!F11 -> 3.3609881
A12: Ramme 150/70 | B12: =('2018'!B12*Faktor!$B$7)+'2018'!B12 -> 15.653491 | E12: Samlerør til aludr. | F12: =('2018'!F12*Faktor!$B$7)+'2018'!F12 -> 12.002047
A13: Ramme 100/70 | B13: =('2018'!B13*Faktor!$B$7)+'2018'!B13 -> 15.653491 | E13: Flapper/Singel | F13: =('2018'!F13*Faktor!$B$7)+'2018'!F13 -> 3.3609881
A14: Ramme 80/70 | B14: =('2018'!B14*Faktor!$B$7)+'2018'!B14 -> 15.653491 | E14: Fastkobling | F14: =('2018'!F14*Faktor!$B$7)+'2018'!F14 -> 3.3609881
A15: Ramme 66/70 | B15: =('2018'!B15*Faktor!$B$7)+'2018'!B15 -> 15.653491 | E15: Drejekobling | F15: =('2018'!F15*Faktor!$B$7)+'2018'!F15 -> 3.3609881
A16: Ramme Kat. 2 tillæg | B16: =('2018'!B16*Faktor!$B$7)+'2018'!B16 -> 2.3236461 | E16: Kipfingerkobling | F16: =('2018'!F16*Faktor!$B$7)+'2018'!F16 -> 3.3609881
A17: Gulvplade 300/70 | B17: =('2018'!B17*Faktor!$B$7)+'2018'!B17 -> 5.3526847 | E17: SK Kobling | F17: =('2018'!F17*Faktor!$B$7)+'2018'!F17 -> 3.3609881
A18: Gulvplade 250/70 | B18: =('2018'!B18*Faktor!$B$7)+'2018'!B18 -> 5.3526847 | E18: Rørsamler | F18: =('2018'!F18*Faktor!$B$7)+'2018'!F18 -> 3.3609881
... A47: B Rør | B47: =('2018'!B47*Faktor!$B$7)+'2018'!B47 -> 6.7738433 | E47: Plader pr kvm | F47: =('2018'!F47*Faktor!$B$7)+'2018'!F47 -> 6.9086977
A48: Konsol 140 | B48: =('2018'!B48*Faktor!$B$7)+'2018'!B48 -> 23.194967 | E48: Planker M | F48: 10.35
A49: Konsol 100 | B49: =('2018'!B49*Faktor!$B$7)+'2018'!B49 -> 16.234402 | E49: Hjulkonsoller | F49: =('2018'!F49*Faktor!$B$7)+'2018'!F49 -> 10.172973
A50: Konsol 70 | B50: =('2018'!B50*Faktor!$B$7)+'2018'!B50 -> 12.759307 | E50: Kegle m. fod | F50: =('2018'!F50*Faktor!$B$7)+'2018'!F50 -> 8.69372
A51: Konsol 35 | B51: =('2018'!B51*Faktor!$B$7)+'2018'!B51 -> 9.2945843 | E51: Montagepris
A52: Fodspark 300 | B52: =('2018'!B52*Faktor!$B$7)+'2018'!B52 -> 5.2904442 | E52: Demontagepris
A53: Fodspark 250 | B53: =('2018'!B53*Faktor!$B$7)+'2018'!B53 -> 5.2904442 | E53: Luk af hul | F53: 2.9
A54: Fodspark 200 | B54: =('2018'!B54*Faktor!$B$7)+'2018'!B54 -> 5.2904442 | E54: Tillæg %+
A55: Fodspark 150 | B55: =('2018'!B55*Faktor!$B$7)+'2018'!B55 -> 5.2904442
A56: Fodspark 125 | B56: =('2018'!B56*Faktor!$B$7)+'2018'!B56 -> 5.2904442
A57: Kanthæk 300 | B57: =('2018'!B57*Faktor!$B$7)+'2018'!B57 -> 23.56841 | E57: Skur/dyrtid | F57: 60.48
A58: Kanthæk 250 | B58: =('2018'!B58*Faktor!$B$7)+'2018'!B58 -> 23.56841 | E58: Km. | F58: 1.78
A59: Kanthæk 200 | B59: =('2018'!B59*Faktor!$B$7)+'2018'!B59 -> 23.56841 | E59: Samlet pris
A60: Kanthæk 70 | B60: =('2018'!B60*Faktor!$B$7)+'2018'!B60 -> 23.56841 | E60: Pris pr time

Sheet 2020
E1: Bosta 2020
A2: Sted | E2: Mont.
A3: Opgave | E3: Demo
A4: Kunde | E4: Montør
A5: Sag nr.
A6: Dato
B7: Pris | C7: Antal | D7: I alt | F7: Pris | G7: Antal | H7: I alt
A8: Spindelfod kort | B8: =('2019'!B7*Faktor!$B$8)+'2019'!B7 -> 2.2983038 | E8: Tværprofil aludr. | F8: =('2019'!F7*Faktor!$B$8)+'2019'!F7 -> 13.027252
A9: Spindelfod lang | B9: =('2019'!B8*Faktor!$B$8)+'2019'!B8 -> 2.2983038 | E9: Alu. Drager pr. m. | F9: =('2019'!F8*Faktor!$B$8)+'2019'!F8 -> 14.700671
A10: Vippefod | B10: =('2019'!B9*Faktor!$B$8)+'2019'!B9 -> 3.802263 | E10: Gelændertvinge | F10: =('2019'!F9*Faktor!$B$8)+'2019'!F9 -> 3.4315688
A11: Strø / trykudligner | B11: =('2019'!B10*Faktor!$B$8)+'2019'!B10 -> 1.5278857 | E11: Tværprofin ram. | F11: =('2019'!F10*Faktor!$B$8)+'2019'!F10 -> 13.027252
A12: Ramme 200/70 | B12: =('2019'!B11*Faktor!$B$8)+'2019'!B11 -> 15.982214 | E12: Dæklås | F12: =('2019'!F11*Faktor!$B$8)+'2019'!F11 -> 3.4315688
A13: Ramme 150/70 | B13: =('2019'!B12*Faktor!$B$8)+'2019'!B12 -> 15.982214 | E13: Samlerør til aludr. | F13: =('2019'!F12*Faktor!$B$8)+'2019'!F12 -> 12.25409
A14: Ramme 100/70 | B14: =('2019'!B13*Faktor!$B$8)+'2019'!B13 -> 15.982214 | E14: Flapper/Singel | F14: =('2019'!F13*Faktor!$B$8)+'2019'!F13 -> 3.4315688
A15: Ramme 80/70 | B15: =('2019'!B14*Faktor!$B$8)+'2019'!B14 -> 15.982214 | E15: Fastkobling | F15: =('2019'!F14*Faktor!$B$8)+'2019'!F14 -> 3.4315688
A16: Ramme 66/70 | B16: =('2019'!B15*Faktor!$B$8)+'2019'!B15 -> 15.982214 | E16: Drejekobling | F16: =('2019'!F15*Faktor!$B$8)+'2019'!F15 -> 3.4315688
A17: Ramme Kat. 2 tillæg | B17: =('2019'!B16*Faktor!$B$8)+'2019'!B16 -> 2.3724426 | E17: Kipfingerkobling | F17: =('2019'!F16*Faktor!$B$8)+'2019'!F16 -> 3.4315688
A18: Gulvplade 300/70 | B18: =('2019'!B17*Faktor!$B$8)+'2019'!B17 -> 5.4650911 | E18: SK Kobling | F18: =('2019'!F17*Faktor!$B$8)+'2019'!F17 -> 3.4315688
A19: Gulvplade 250/70 | B19: =('2019'!B18*Faktor!$B$8)+'2019'!B18 -> 5.4650911 | E19: Rørsamler | F19: =('2019'!F18*Faktor!$B$8)+'2019'!F18 -> 3.4315688
... A51: Konsol 70 | B51: =('2019'!B50*Faktor!$B$8)+'2019'!B50 -> 13.027252 | E51: Kegle m. fod | F51: =('2019'!F50*Faktor!$B$8)+'2019'!F50 -> 8.8762881
A52: Konsol 35 | B52: =('2019'!B51*Faktor!$B$8)+'2019'!B51 -> 9.4897706 | E52: Montagepris
A53: Fodspark 300 | B53: =('2019'!B52*Faktor!$B$8)+'2019'!B52 -> 5.4015435 | E53: Demontagepris
A54: Fodspark 250 | B54: =('2019'!B53*Faktor!$B$8)+'2019'!B53 -> 5.4015435 | E54: Luk af hul | F54: =('2019'!F53*Faktor!$B$8)+'2019'!F53 -> 2.9609
A55: Fodspark 200 | B55: =('2019'!B54*Faktor!$B$8)+'2019'!B54 -> 5.4015435 | E55: Tillæg %+
A56: Fodspark 150 | B56: =('2019'!B55*Faktor!$B$8)+'2019'!B55 -> 5.4015435 | E56: Opskydeligt rækværk | F56: 9.15
A57: Fodspark 125 | B57: =('2019'!B56*Faktor!$B$8)+'2019'!B56 -> 5.4015435 | E57: Skur/dyrtid | F57: =('2019'!F57*Faktor!$B$8)+'2019'!F57 -> 61.75008
A58: Kanthæk 300 | B58: =('2019'!B57*Faktor!$B$8)+'2019'!B57 -> 24.063347 | E58: Km. | F58: 1.81
A59: Kanthæk 250 | B59: =('2019'!B58*Faktor!$B$8)+'2019'!B58 -> 24.063347 | E59: Samlet pris
A60: Kanthæk 200 | B60: =('2019'!B59*Faktor!$B$8)+'2019'!B59 -> 24.063347 | E60: Pris pr time
A61: Kanthæk 70 | B61: 24.06
A62: Bemærkninger:

Sheet 2021
E1: Bosta 2021
A2: Sted | E2: Mont.
A3: Opgave | E3: Demo
A4: Kunde | E4: Dato
A5: Sag nr.
B7: Pris | C7: Antal | D7: I alt | F7: Pris | G7: Antal | H7: I alt
A8: Spindelfod kort | B8: 2.36 | E8: Tværprofil aludr. | F8: 13.34
A9: Spindelfod lang | B9: 2.36 | E9: Alu. Drager pr. m. | F9: 15.05
A10: Vippefod | B10: 3.89 | E10: Gelændertvinge | F10: 3.51
A11: Strø / trykudligner | B11: 1.56 | E11: Tværprofin ram. | F11: 13.34
A12: Ramme 200/70 | B12: 16.37 | E12: Dæklås | F12: 3.51
A13: Ramme 150/70 | B13: 16.37 | E13: Samlerør til aludr. | F13: 12.55
A14: Ramme 100/70 | B14: 16.37 | E14: Flapper/Singel | F14: 3.51
A15: Ramme 80/70 | B15: 16.37 | E15: Fastkobling | F15: 3.51
A16: Ramme 66/70 | B16: 16.37 | E16: Drejekobling | F16: 3.51
A17: Ramme Kat. 2 tillæg | B17: 2.43 | E17: Kipfingerkobling | F17: 3.51
A18: Gulvplade 300/70 | B18: 5.6 | E18: SK Kobling | F18: 3.51
A19: Gulvplade 250/70 | B19: 5.6 | E19: Rørsamler | F19: 3.51
... A27: Gulvplade 150/35 | B27: 4.21 | E27: Rør Anker | F27: 9.04
A28: Gulvplade 125/35 | B28: 4.21 | E28: Reklameskilt | F28: =('2019'!F27*Faktor!$B$8)+'2019'!F27 -> 8.741169
A29: Stigedæk 300/70 | B29: 8.87 | E29: Grøn skilt | F29: 5
A30: Stigedæk 250/70 | B30: 8.87 | E30: Startprofil til trappe | F30: 3.63
A31: Stigedæk 200/70 | B31: 8.87 | E31: Alu trappeløb | F31: 45.17
A32: Udkrag.70 tillæg | B32: 5.6 | E32: Gelænder trpl | F32: 11.3
A33: Udkrag.35 tillæg | B33: 4.21 | E33: Dobb bundramme | F33: 39.48
A34: Stige 200 | B34: 3.98 | E34: Tragt | F34: 34.32
A35: Stige 300 | B35: 3.98 | E35: Skaktrør | F35: 34.32
A36: Stigestøtte | B36: =('2019'!B35*Faktor!$B$8)+'2019'!B35 -> 2.5138255 | E36: Alu.bro pr. m | F36: 13.29
A37: Diagonaler 200 | B37: 6.4 | E37: Net pr kvm | F37: 2.5
A38: Diagonaler 203 | B38: 6.4 | E38: Plast pr kvm | F38: 6.03
A39: Gelænder 125 | B39: 2.75 | E39: Blindrum | F39: 5.6
A40: Gelænder 150 | B40: 2.75 | E40: Geda hejs | F40: 266.73
A41: Gelænder 200 | B41: 2.75 | E41: El hejs | F41: 134.71
A42: Gelænder 250 | B42: 2.75 | E42: Kegle u.fod | F42: =('2019'!F45*Faktor!$B$8)+'2019'!F45 -> 5.4047656
A43: Gelænder 300 | B43: 2.75 | E43: Kirkefod | F43: 6
A44: Tvær Gel. 70 | B44: 2.75 | E44: Plader pr kvm | F44: 7.22
A45: Dob. Tværgelænder | B45: 5.46 | E45: Planker M | F45: 10.79
A46: Dob. G | B46: 16.37 | E46: Hjulkonsoller | F46: 10.61
A47: L Rør | B47: 16.37 | E47: Kegle m. fod | F47: 9.04
A48: B Rør | B48: 7.09
...

Sheet 2023
E1: Bosta 2023
A2: Sted | E2: Mont.
A3: Opgave | E3: Demo
A4: Kunde | E4: Dato
A5: Sag nr.
B6: Pris | C6: Antal | D6: I alt | F6: Pris | G6: Antal | H6: I alt
A7: Spindelfod kort | B7: 2.5 | E7: Alu. Drager pr. m. | F7: 15.99
A8: Spindelfod lang | B8: 2.5 | E8: Gelændertvinge | F8: 3.73
A9: Vippefod | B9: 4.14 | E9: Tværprofin ram. | F9: 14.16
A10: Strø / trykudligner | B10: 1.66 | E10: Dæklås | F10: 3.73
A11: Ramme 200/70 | B11: 15.61 | E11: Samlerør til aludr. | F11: 13.33
A12: Ramme 150/70 | B12: 15.61 | E12: Flapper/Singel | F12: 3.73
A13: Ramme 100/70 | B13: 15.61 | E13: Fastkobling | F13: 3.73
A14: Ramme 80/70 | B14: 15.61 | E14: Drejekobling | F14: 3.73
A15: Ramme 66/70 | B15: 15.61 | E15: Kipfingerkobling | F15: 3.73
A16: Gulvplade 300/70 | B16: 15.61 | E16: SK Kobling | F16: 3.73
A17: Gulvplade 250/70 | B17: 11.71 | E17: Rørsamler | F17: 3.73
A18: Gulvplade 200/70 | B18: 11.71 | E18: Stilladsrør 1M | F18: 5.15
A19: Gulvplade 150/70 | B19: 7.81 | E19: Stilladsrør 2M | F19: =F18*2 -> 10.3
A20: Gulvplade 125/70 | B20: 7.81 | E20: Stilladsrør 3M | F20: =F18*3 -> 15.45
A21: Gulvplade 70/70 | B21: 7.81 | E21: Stilladsrør 4M | F21: =F18*4 -> 20.6
A22: Gulvplade 300/35 | B22: 7.81 | E22: Stilladsrør 5M | F22: =F18*5 -> 25.75
A23: Gulvplade 250/35 | B23: 5.85 | E23: Stilladsrør 6M | F23: =F18*6 -> 30.9
A24: Gulvplade 200/35 | B24: 5.85 | E24: Stilladsrør 6M alu | F24: =3.73*6 -> 22.38
A25: Gulvplade 150/35 | B25: 3.9 | E25: Bøjleanker | F25: 13.66
A26: Gulvplade 125/35 | B26: 3.9 | E26: Rør anker alu | F26: 13.66
A27: Stigedæk 300/70 | B27: 19.51 | E27: Rør anker stål | F27: 17.56
A28: Stigedæk 250/70 | B28: 15.61 | E28: Reklameskilt | F28: 9.09
A29: Stigedæk 200/70 | B29: 11.71 | E29: Grøn skilt | F29: 5
A30: Ståldæk 300/35 | B30: 14.64 | E30: Startprofil til trappe | F30: 3.86
A31: Ståldæk 250/35 | B31: 9.76 | E31: Alu trappeløb | F31: 47.96
A32: Ståldæk 200/35 | B32: 7.81 | E32: Gelænder trpl | F32: 12.51
A33: Stige 200 | B33: 4.21 | E33: Dobb bundramme | F33: 41.92
A34: Stige 300 | B34: 4.21 | E34: Tragt | F34: 36.43
A35: Stigestøtte | B35: 2.67 | E35: Skaktrør | F35: 35.43
A36: Diagonaler 200 | B36: 8.78 | E36: Alu.bro pr. m | F36: 14.13
... A47: B Rør | B47: 7.81 | E47: Bræt rød/hvid | F47: 5.86
A48: Konsol 140 | B48: 25.75
A49: Konsol 100 | B49: 18.02 | E49: Montagepris
A50: Konsol 70 | B50: 14.16 | E50: Demontagepris
...

Sheet 2024
E1: Bosta 2024
A2: Sted | E2: Mont.
A3: Opgave | E3: Demo
A4: Kunde | E4: Dato
A5: Sag nr.
B6: Pris | C6: Antal | D6: I alt | F6: Pris | G6: Antal | H6: I alt
A7: Spindelfod kort | B7: =('2023'!B7/100)*103.9 -> 2.5975 | E7: Alu. Drager pr. m. | F7: =('2023'!F7/100)*103.9 -> 16.61361
A8: Spindelfod lang | B8: =('2023'!B8/100)*103.9 -> 2.5975 | E8: Gelændertvinge | F8: =('2023'!F8/100)*103.9 -> 3.87547
A9: Vippefod | B9: =('2023'!B9/100)*103.9 -> 4.30146 | E9: Tværprofin ram. | F9: =('2023'!F9/100)*103.9 -> 14.71224
A10: Strø / trykudligner | B10: =('2023'!B10/100)*103.9 -> 1.72474 | E10: Dæklås | F10: =('2023'!F10/100)*103.9 -> 3.87547
A11: Ramme 200/70 | B11: =('2023'!B11/100)*103.9 -> 16.21879 | E11: Samlerør til aludr. | F11: =('2023'!F11/100)*103.9 -> 13.84987
A12: Ramme 150/70 | B12: =('2023'!B12/100)*103.9 -> 16.21879 | E12: Flapper/Singel | F12: =('2023'!F12/100)*103.9 -> 3.87547
A13: Ramme 100/70 | B13: =('2023'!B13/100)*103.9 -> 16.21879 | E13: Fastkobling | F13: =('2023'!F13/100)*103.9 -> 3.87547
A14: Ramme 80/70 | B14: =('2023'!B14/100)*103.9 -> 16.21879 | E14: Drejekobling | F14: =('2023'!F14/100)*103.9 -> 3.87547
A15: Ramme 66/70 | B15: =('2023'!B15/100)*103.9 -> 16.21879 | E15: Kipfingerkobling | F15: =('2023'!F15/100)*103.9 -> 3.87547
A16: Gulvplade 300/70 | B16: =('2023'!B16/100)*103.9 -> 16.21879 | E16: SK Kobling | F16: =('2023'!F16/100)*103.9 -> 3.87547
A17: Gulvplade 250/70 | B17: =('2023'!B17/100)*103.9 -> 12.16669 | E17: Rørsamler | F17: =('2023'!F17/100)*103.9 -> 3.87547
A18: Gulvplade 200/70 | B18: =('2023'!B18/100)*103.9 -> 12.16669 | E18: Stilladsrør 1M | F18: =('2023'!F18/100)*103.9 -> 5.35085
... A22: Gulvplade 300/35 | B22: =('2023'!B22/100)*103.9 -> 8.11459 | E22: Stilladsrør 5M | F22: =('2023'!F22/100)*103.9 -> 26.75425
A23: Gulvplade 250/35 | B23: =('2023'!B23/100)*103.9 -> 6.07815 | E23: Stilladsrør 6M | F23: 32.1
A24: Gulvplade 200/35 | B24: =('2023'!B24/100)*103.9 -> 6.07815 | E24: Stilladsrør 6M alu | F24: 23.28
A25: Gulvplade 150/35 | B25: =('2023'!B25/100)*103.9 -> 4.0521 | E25: Bøjleanker | F25: =('2023'!F25/100)*103.9 -> 14.19274
A26: Gulvplade 125/35 | B26: =('2023'!B26/100)*103.9 -> 4.0521 | E26: Rør anker alu | F26: =('2023'!F26/100)*103.9 -> 14.19274
A27: Stigedæk 300/70 | B27: =('2023'!B27/100)*103.9 -> 20.27089 | E27: Rør anker stål | F27: =('2023'!F27/100)*103.9 -> 18.24484
A28: Stigedæk 250/70 | B28: =('2023'!B28/100)*103.9 -> 16.21879 | E28: Reklameskilt | F28: 9.45
A29: Stigedæk 200/70 | B29: =('2023'!B29/100)*103.9 -> 12.16669 | E29: Grøn skilt | F29: 5
A30: Ståldæk 300/35 | B30: =('2023'!B30/100)*103.9 -> 15.21096 | E30: Startprofil til trappe | F30: =('2023'!F30/100)*103.9 -> 4.01054
A31: Ståldæk 250/35 | B31: =('2023'!B31/100)*103.9 -> 10.14064 | E31: Alu trappeløb | F31: 49.73
A32: Ståldæk 200/35 | B32: =('2023'!B32/100)*103.9 -> 8.11459 | E32: Gelænder trpl | F32: =('2023'!F32/100)*103.9 -> 12.99789
A33: Stige 200 | B33: =('2023'!B33/100)*103.9 -> 4.37419 | E33: Dobb bundramme | F33: =('2023'!F33/100)*103.9 -> 43.55488
A34: Stige 300 | B34: =('2023'!B34/100)*103.9 -> 4.37419 | E34: Tragt | F34: =('2023'!F34/100)*103.9 -> 37.85077
A35: Stigestøtte | B35: 2.78 | E35: Skaktrør | F35: 37.85
A36: Diagonaler 200 | B36: =('2023'!B36/100)*103.9 -> 9.12242 | E36: Alu.bro pr. m | F36: 14.68
A37: Diagonaler 203 | B37: =('2023'!B37/100)*103.9 -> 9.12242 | E37: Net pr kvm | F37: =('2023'!F37/100)*103.9 -> 2.76374
A38: Gelænder 125 | B38: =('2023'!B38/100)*103.9 -> 3.04427 | E38: Plast pr kvm | F38: =('2023'!F38/100)*103.9 -> 6.63921
A39: Gelænder 150 | B39: =('2023'!B39/100)*103.9 -> 3.04427 | E39: Geda hejs | F39: =('2023'!F39/100)*103.9 -> 294.25519
A40: Gelænder 200 | B40: 3.81 | E40: El hejs | F40: =('2023'!F40/100)*103.9 -> 148.61856
A41: Gelænder 250 | B41: 3.81 | E41: Kegle u.fod | F41: 5.97
A42: Gelænder 300 | B42: =('2023'!B42/100)*103.9 -> 5.07032 | E42: Kirkefod | F42: =('2023'!F42/100)*103.9 -> 6.62882
A43: Tvær Gel. 70 | B43: =('2023'!B43/100)*103.9 -> 3.04427 | E43: Plader pr kvm | F43: =('2023'!F43/100)*103.9 -> 7.96913
...

Sheet 2025
E1: Bosta 2025
A2: Sted | E2: Mont.
A3: Opgave | E3: Demo
A4: Kunde | E4: Dato
A5: Sag nr.
B6: Pris | C6: Antal | D6: I alt | F6: Pris | G6: Antal | H6: I alt
A7: Spindelfod kort | B7: =('2024'!B7/100)*103 -> 2.675425 | E7: Alu. Drager pr. m. | F7: 17.12
A8: Spindelfod lang | B8: =('2024'!B8/100)*103 -> 2.675425 | E8: Gelændertvinge | F8: =('2024'!F8/100)*103 -> 3.9917341
A9: Vippefod | B9: =('2024'!B9/100)*103 -> 4.4305038 | E9: Tværprofin ram. | F9: =('2024'!F9/100)*103 -> 15.153607
A10: Strø / trykudligner | B10: 1.77 | E10: Dæklås | F10: =('2024'!F10/100)*103 -> 3.9917341
A11: Ramme 200/70 | B11: =('2024'!B11/100)*103 -> 16.705354 | E11: Samlerør til aludr. | F11: 14.26
A12: Ramme 150/70 | B12: =('2024'!B12/100)*103 -> 16.705354 | E12: Flapper/Singel | F12: =('2024'!F12/100)*103 -> 3.9917341
A13: Ramme 100/70 | B13: =('2024'!B13/100)*103 -> 16.705354 | E13: Fastkobling | F13: =('2024'!F13/100)*103 -> 3.9917341
A14: Ramme 80/70 | B14: =('2024'!B14/100)*103 -> 16.705354 | E14: Drejekobling | F14: =('2024'!F14/100)*103 -> 3.9917341
A15: Ramme 66/70 | B15: =('2024'!B15/100)*103 -> 16.705354 | E15: Kipfingerkobling | F15: =('2024'!F15/100)*103 -> 3.9917341
A16: Gulvplade 300/70 | B16: =('2024'!B16/100)*103 -> 16.705354 | E16: SK Kobling | F16: =('2024'!F16/100)*103 -> 3.9917341
A17: Gulvplade 250/70 | B17: =('2024'!B17/100)*103 -> 12.531691 | E17: Rørsamler | F17: =('2024'!F17/100)*103 -> 3.9917341
A18: Gulvplade 200/70 | B18: =('2024'!B18/100)*103 -> 12.531691 | E18: Stilladsrør 1M | F18: =('2024'!F18/100)*103 -> 5.5113755
A19: Gulvplade 150/70 | B19: 8.35 | E19: Stilladsrør 2M | F19: =('2024'!F19/100)*103 -> 11.022751
A20: Gulvplade 125/70 | B20: 8.35 | E20: Stilladsrør 3M | F20: =('2024'!F20/100)*103 -> 16.534126
A21: Gulvplade 70/70 | B21: 8.35 | E21: Stilladsrør 4M | F21: 22.04
A22: Gulvplade 300/35 | B22: 8.35 | E22: Stilladsrør 5M | F22: 27.55
A23: Gulvplade 250/35 | B23: =('2024'!B23/100)*103 -> 6.2604945 | E23: Stilladsrør 6M | F23: =('2024'!F23/100)*103 -> 33.063
A24: Gulvplade 200/35 | B24: =('2024'!B24/100)*103 -> 6.2604945 | E24: Stilladsrør 6M alu | F24: 23.94
A25: Gulvplade 150/35 | B25: 4.18 | E25: Bøjleanker | F25: =('2024'!F25/100)*103 -> 14.618522
A26: Gulvplade 125/35 | B26: 4.18 | E26: Rør anker alu | F26: =('2024'!F26/100)*103 -> 14.618522
A27: Stigedæk 300/70 | B27: =('2024'!B27/100)*103 -> 20.879017 | E27: Rør anker stål | F27: =('2024'!F27/100)*103 -> 18.792185
A28: Stigedæk 250/70 | B28: =('2024'!B28/100)*103 -> 16.705354 | E28: Reklameskilt | F28: =('2024'!F28/100)*103 -> 9.7335
A29: Stigedæk 200/70 | B29: =('2024'!B29/100)*103 -> 12.531691 | E29: Grøn skilt | F29: =('2024'!F29/100)*103 -> 5.15
A30: Ståldæk 300/35 | B30: 15.66 | E30: Startprofil til trappe | F30: =('2024'!F30/100)*103 -> 4.1308562
A31: Ståldæk 250/35 | B31: =('2024'!B31/100)*103 -> 10.444859 | E31: Alu trappeløb | F31: =('2024'!F31/100)*103 -> 51.2219
A32: Ståldæk 200/35 | B32: 8.35 | E32: Gelænder trpl | F32: =('2024'!F32/100)*103 -> 13.387827
A33: Stige 200 | B33: =('2024'!B33/100)*103 -> 4.5054157 | E33: Dobb bundramme | F33: =('2024'!F33/100)*103 -> 44.861526
A34: Stige 300 | B34: =('2024'!B34/100)*103 -> 4.5054157 | E34: Tragt | F34: =('2024'!F34/100)*103 -> 38.986293
A35: Stigestøtte | B35: =('2024'!B35/100)*103 -> 2.8634 | E35: Skaktrør | F35: =('2024'!F35/100)*103 -> 38.9855
A36: Diagonaler 200 | B36: =('2024'!B36/100)*103 -> 9.3960926 | E36: Alu.bro pr. m | F36: =('2024'!F36/100)*103 -> 15.1204
A37: Diagonaler 203 | B37: =('2024'!B37/100)*103 -> 9.3960926 | E37: Net pr kvm | F37: =('2024'!F37/100)*103 -> 2.8466522
A38: Gelænder 125 | B38: 3.13 | E38: Plast pr kvm | F38: =('2024'!F38/100)*103 -> 6.8383863
A39: Gelænder 150 | B39: 3.13 | E39: Geda hejs | F39: =('2024'!F39/100)*103 -> 303.08285
A40: Gelænder 200 | B40: =('2024'!B40/100)*103 -> 3.9243 | E40: El hejs | F40: 153.07
...
