Workbook

Sheet Faktor
A1: Forøgelses faktor
A3: 2015 | B3: 0.014
A4: 2016 | B4: 0.019
A5: 2017 | B5: 0.014
A6: 2018 | B6: 0.019
A7: 2019 | B7: 0.021
A8: 2020 | B8: 0.021
A9: 2021 | B9: 0.021
A10: 2022 | B10: 0.021

Sheet 2014
E1: HAKI
A2: Sted | F2: Dato
A3: Opgave | F3: Mont
F4: Demo
A5: Kunde | F5: Montør
A6: Sag nr.
B8: Pris / | C8: Antal | D8: Pris i alt | F8: Pris / | G8: Antal | H8: Pris i alt
B9: enh. | F9: enh.
A10: Spindelfod kort | B10: 2.06
A11: BPF Fodsokkel | B11: 2.06 | E11: Diagonalstag 3.0 m | F11: 5.61
E12: Diagonalstag 1,6 m | F12: 5.61
A13: Strø / trykudligner | B13: 1.37
A15: FS 3,0 m Søjle | B15: 31.48 | E15: Traller 2.2 x 0.35m | F15: 3.23
A16: FS 2,0 m Søjle | B16: 20.99 | E16: Traller 2.2 x 0.5m | F16: 4.68
A17: FS 1,5 m Søjle | B17: 15.57 | E17: Kantbrædder | F17: 4.77
A18: FS 1.0 m Søjle | B18: 10.49 | E18: Låsejern | F18: 0.87
A19: FS 0,5 m Søjle | B19: 5.24
E20: Stiger til 3m | F20: 3.49
A21: LB 4,0 m bjælke | B21: 18.43
A22: LB 3,6 m bjælke | B22: 11.55
A23: LB 3,0 m bjælke | B23: 7.81 | E23: Koblinger fast | F23: 3.08
E24: Koblinger dreje | F24: 3.08
A25: TB 1,9 m bjælke | B25: 4.68 | E25: Koblinger SK | F25: 3.08
A26: TB 1,6 m bjælke | B26: 4.68 | E26: Koblinger Kipfinger | F26: 3.08
A27: TB 1,2 m bjælke | B27: 4.68 | E27: Koblinger singel | F27: 3.08
A28: TB 1,0 m bjælke | B28: 4.68 | E28: Koblinger samler | F28: 3.08
A29: TB 0,5 m bjælke | B29: 4.68
E30: Net pr. m2 | F30: 2.2
A31: SKR 4.0 m rækværk | B31: 9.52 | E31: Plastik pr. m2 | F31: 5.28
A32: SKR 3.6 m rækværk | B32: 5.44
A33: SKR 3.0 m rækværk | B33: 2.72
A34: SKR 1.9 m rækværk | B34: 2.72
A35: SKR 1.6 m rækværk | B35: 2.72 | E35: Grøn skilt | F35: 0
A36: SKR 1.2 m rækværk | B36: 2.72 | E36: Reklameskilt | F36: 7.98
A37: SKR 1.0 m rækværk | B37: 2.72
A41: Bøjleanker | B41: 6.33 | E41: Montage pris
A42: Røranker | B42: 7.92 | E42: Demontage pris
E43: Luk af hul | F43: 2.66
A44: Stilladsrør 1M | B44: 4.25 | E44: Tillæg % +
A45: Stilladsrør 2M | B45: 8.5 | E45: Skur/Dyrtid | F45: 55.26
...

Sheet 2015
E1: HAKI
A2: Sted | F2: Dato
A3: Opgave | F3: Mont
F4: Demo
A5: Kunde | F5: Montør
A6: Sag nr.
B8: Pris / | C8: Antal | D8: Pris i alt | F8: Pris / | G8: Antal | H8: Pris i alt
B9: enh. | F9: enh.
A10: Spindelfod kort | B10: =('2014'!B10*Faktor!$B$3)+'2014'!B10 -> 2.08884
A11: BPF Fodsokkel | B11: =('2014'!B11*Faktor!$B$3)+'2014'!B11 -> 2.08884 | E11: Diagonalstag 3.0 m | F11: =('2014'!F11*Faktor!$B$3)+'2014'!F11 -> 5.68854
E12: Diagonalstag 1,6 m | F12: =('2014'!F12*Faktor!$B$3)+'2014'!F12 -> 5.68854
A13: Strø / trykudligner | B13: =('2014'!B13*Faktor!$B$3)+'2014'!B13 -> 1.38918
A15: FS 3,0 m Søjle | B15: =('2014'!B15*Faktor!$B$3)+'2014'!B15 -> 31.92072 | E15: Traller 2.2 x 0.35m | F15: =('2014'!F15*Faktor!$B$3)+'2014'!F15 -> 3.27522
A16: FS 2,0 m Søjle | B16: =('2014'!B16*Faktor!$B$3)+'2014'!B16 -> 21.28386 | E16: Traller 2.2 x 0.5m | F16: =('2014'!F16*Faktor!$B$3)+'2014'!F16 -> 4.74552
A17: FS 1,5 m Søjle | B17: =('2014'!B17*Faktor!$B$3)+'2014'!B17 -> 15.78798 | E17: Kantbrædder | F17: =('2014'!F17*Faktor!$B$3)+'2014'!F17 -> 4.83678
A18: FS 1.0 m Søjle | B18: =('2014'!B18*Faktor!$B$3)+'2014'!B18 -> 10.63686 | E18: Låsejern | F18: =('2014'!F18*Faktor!$B$3)+'2014'!F18 -> 0.88218
A19: FS 0,5 m Søjle | B19: =('2014'!B19*Faktor!$B$3)+'2014'!B19 -> 5.31336
E20: Stiger til 3m | F20: =('2014'!F20*Faktor!$B$3)+'2014'!F20 -> 3.53886
A21: LB 4,0 m bjælke | B21: =('2014'!B21*Faktor!$B$3)+'2014'!B21 -> 18.68802
A22: LB 3,6 m bjælke | B22: =('2014'!B22*Faktor!$B$3)+'2014'!B22 -> 11.7117
A23: LB 3,0 m bjælke | B23: =('2014'!B23*Faktor!$B$3)+'2014'!B23 -> 7.91934 | E23: Koblinger fast | F23: =('2014'!F23*Faktor!$B$3)+'2014'!F23 -> 3.12312
E24: Koblinger dreje | F24: =('2014'!F24*Faktor!$B$3)+'2014'!F24 -> 3.12312
A25: TB 1,9 m bjælke | B25: =('2014'!B25*Faktor!$B$3)+'2014'!B25 -> 4.74552 | E25: Koblinger SK | F25: =('2014'!F25*Faktor!$B$3)+'2014'!F25 -> 3.12312
A26: TB 1,6 m bjælke | B26: =('2014'!B26*Faktor!$B$3)+'2014'!B26 -> 4.74552 | E26: Koblinger Kipfinger | F26: =('2014'!F26*Faktor!$B$3)+'2014'!F26 -> 3.12312
A27: TB 1,2 m bjælke | B27: =('2014'!B27*Faktor!$B$3)+'2014'!B27 -> 4.74552 | E27: Koblinger singel | F27: =('2014'!F27*Faktor!$B$3)+'2014'!F27 -> 3.12312
A28: TB 1,0 m bjælke | B28: =('2014'!B28*Faktor!$B$3)+'2014'!B28 -> 4.74552 | E28: Koblinger samler | F28: =('2014'!F28*Faktor!$B$3)+'2014'!F28 -> 3.12312
A29: TB 0,5 m bjælke | B29: =('2014'!B29*Faktor!$B$3)+'2014'!B29 -> 4.74552
E30: Net pr. m2 | F30: =('2014'!F30*Faktor!$B$3)+'2014'!F30 -> 2.2308
A31: SKR 4.0 m rækværk | B31: =('2014'!B31*Faktor!$B$3)+'2014'!B31 -> 9.65328 | E31: Plastik pr. m2 | F31: =('2014'!F31*Faktor!$B$3)+'2014'!F31 -> 5.35392
A32: SKR 3.6 m rækværk | B32: =('2014'!B32*Faktor!$B$3)+'2014'!B32 -> 5.51616
A33: SKR 3.0 m rækværk | B33: =('2014'!B33*Faktor!$B$3)+'2014'!B33 -> 2.75808
A34: SKR 1.9 m rækværk | B34: =('2014'!B34*Faktor!$B$3)+'2014'!B34 -> 2.75808
A35: SKR 1.6 m rækværk | B35: =('2014'!B35*Faktor!$B$3)+'2014'!B35 -> 2.75808 | E35: Grøn skilt | F35: =('2014'!F35*Faktor!$B$3)+'2014'!F35 -> 0
A36: SKR 1.2 m rækværk | B36: =('2014'!B36*Faktor!$B$3)+'2014'!B36 -> 2.75808 | E36: Reklameskilt | F36: ='2014'!F36 -> 7.98
A37: SKR 1.0 m rækværk | B37: =('2014'!B37*Faktor!$B$3)+'2014'!B37 -> 2.75808
A41: Bøjleanker | B41: =('2014'!B41*Faktor!$B$3)+'2014'!B41 -> 6.41862 | E41: Montage pris
A42: Røranker | B42: =('2014'!B42*Faktor!$B$3)+'2014'!B42 -> 8.03088 | E42: Demontage pris
E43: Luk af hul | F43: =('2014'!F43*Faktor!$B$3)+'2014'!F43 -> 2.69724
A44: Stilladsrør 1M | B44: =('2014'!B44*Faktor!$B$3)+'2014'!B44 -> 4.3095 | E44: Tillæg % +
A45: Stilladsrør 2M | B45: =('2014'!B45*Faktor!$B$3)+'2014'!B45 -> 8.619 | E45: Skur/Dyrtid | F45: =('2014'!F45*Faktor!$B$3)+'2014'!F45 -> 56.03364
...

Sheet 2016
A1: HAKI 2016
A2: Sted | F2: Dato
A3: Opgave | F3: Mont
F4: Demo
A5: Kunde | F5: Montør
A6: Sag nr.
B8: Pris / | C8: Antal | D8: Pris i alt | F8: Pris / | G8: Antal | H8: Pris i alt
B9: enh. | F9: enh.
A10: Spindelfod kort | B10: =('2015'!B10*Faktor!$B$4)+'2015'!B10 -> 2.128528
A11: BPF Fodsokkel | B11: =('2015'!B11*Faktor!$B$4)+'2015'!B11 -> 2.128528 | E11: Diagonalstag 3.0 m | F11: =('2015'!F11*Faktor!$B$4)+'2015'!F11 -> 5.7966223
E12: Diagonalstag 1,6 m | F12: =('2015'!F12*Faktor!$B$4)+'2015'!F12 -> 5.7966223
A13: Strø / trykudligner | B13: =('2015'!B13*Faktor!$B$4)+'2015'!B13 -> 1.4155744
A15: FS 3,0 m Søjle | B15: =('2015'!B15*Faktor!$B$4)+'2015'!B15 -> 32.527214 | E15: Traller 2.2 x 0.35m | F15: =('2015'!F15*Faktor!$B$4)+'2015'!F15 -> 3.3374492
A16: FS 2,0 m Søjle | B16: =('2015'!B16*Faktor!$B$4)+'2015'!B16 -> 21.688253 | E16: Traller 2.2 x 0.5m | F16: =('2015'!F16*Faktor!$B$4)+'2015'!F16 -> 4.8356849
A17: FS 1,5 m Søjle | B17: =('2015'!B17*Faktor!$B$4)+'2015'!B17 -> 16.087952 | E17: Kantbrædder | F17: =('2015'!F17*Faktor!$B$4)+'2015'!F17 -> 4.9286788
A18: FS 1.0 m Søjle | B18: =('2015'!B18*Faktor!$B$4)+'2015'!B18 -> 10.83896 | E18: Låsejern | F18: =('2015'!F18*Faktor!$B$4)+'2015'!F18 -> 0.89894142
A19: FS 0,5 m Søjle | B19: =('2015'!B19*Faktor!$B$4)+'2015'!B19 -> 5.4143138
E20: Stiger til 3m | F20: =('2015'!F20*Faktor!$B$4)+'2015'!F20 -> 3.6060983
A21: LB 4,0 m bjælke | B21: =('2015'!B21*Faktor!$B$4)+'2015'!B21 -> 19.043092
A22: LB 3,6 m bjælke | B22: =('2015'!B22*Faktor!$B$4)+'2015'!B22 -> 11.934222
A23: LB 3,0 m bjælke | B23: =('2015'!B23*Faktor!$B$4)+'2015'!B23 -> 8.0698075 | E23: Koblinger fast | F23: =('2015'!F23*Faktor!$B$4)+'2015'!F23 -> 3.1824593
A24: LB 2,5 m bjælke | B24: 8.07 | E24: Koblinger dreje | F24: =('2015'!F24*Faktor!$B$4)+'2015'!F24 -> 3.1824593
A25: TB 1,9 m bjælke | B25: =('2015'!B25*Faktor!$B$4)+'2015'!B25 -> 4.8356849 | E25: Koblinger SK | F25: =('2015'!F25*Faktor!$B$4)+'2015'!F25 -> 3.1824593
A26: TB 1,6 m bjælke | B26: =('2015'!B26*Faktor!$B$4)+'2015'!B26 -> 4.8356849 | E26: Koblinger Kipfinger | F26: =('2015'!F26*Faktor!$B$4)+'2015'!F26 -> 3.1824593
A27: TB 1,2 m bjælke | B27: =('2015'!B27*Faktor!$B$4)+'2015'!B27 -> 4.8356849 | E27: Koblinger singel | F27: =('2015'!F27*Faktor!$B$4)+'2015'!F27 -> 3.1824593
A28: TB 1,0 m bjælke | B28: =('2015'!B28*Faktor!$B$4)+'2015'!B28 -> 4.8356849 | E28: Koblinger samler | F28: =('2015'!F28*Faktor!$B$4)+'2015'!F28 -> 3.1824593
A29: TB 0,5 m bjælke | B29: =('2015'!B29*Faktor!$B$4)+'2015'!B29 -> 4.8356849
E30: Net pr. m2 | F30: =('2015'!F30*Faktor!$B$4)+'2015'!F30 -> 2.2731852
A31: SKR 4.0 m rækværk | B31: =('2015'!B31*Faktor!$B$4)+'2015'!B31 -> 9.8366923 | E31: Plastik pr. m2 | F31: =('2015'!F31*Faktor!$B$4)+'2015'!F31 -> 5.4556445
A32: SKR 3.6 m rækværk | B32: =('2015'!B32*Faktor!$B$4)+'2015'!B32 -> 5.620967
A33: SKR 3.0 m rækværk | B33: =('2015'!B33*Faktor!$B$4)+'2015'!B33 -> 2.8104835
A34: SKR 1.9 m rækværk | B34: =('2015'!B34*Faktor!$B$4)+'2015'!B34 -> 2.8104835
A35: SKR 1.6 m rækværk | B35: =('2015'!B35*Faktor!$B$4)+'2015'!B35 -> 2.8104835 | E35: Grøn skilt
A36: SKR 1.2 m rækværk | B36: =('2015'!B36*Faktor!$B$4)+'2015'!B36 -> 2.8104835 | E36: Reklameskilt | F36: =('2015'!F36*Faktor!$B$4)+'2015'!F36 -> 8.13162
A37: SKR 1.0 m rækværk | B37: =('2015'!B37*Faktor!$B$4)+'2015'!B37 -> 2.8104835
A41: Bøjleanker | B41: =('2015'!B41*Faktor!$B$4)+'2015'!B41 -> 6.5405738 | E41: Montage pris
A42: Røranker | B42: =('2015'!B42*Faktor!$B$4)+'2015'!B42 -> 8.1834667 | E42: Demontage pris
E43: Luk af hul | F43: =('2015'!F43*Faktor!$B$4)+'2015'!F43 -> 2.7484876
A44: Stilladsrør 1M | B44: =('2015'!B44*Faktor!$B$4)+'2015'!B44 -> 4.3913805 | E44: Tillæg % +
A45: Stilladsrør 2M | B45: =('2015'!B45*Faktor!$B$4)+'2015'!B45 -> 8.782761 | E45: Skur/Dyrtid | F45: =('2015'!F45*Faktor!$B$4)+'2015'!F45 -> 57.098279
...

Sheet 2017
A1: HAKI 2017
A2: Sted | F2: Dato
A3: Opgave | F3: Mont
F4: Demo
A5: Kunde | F5: Montør
A6: Sag nr.
B8: Pris / | C8: Antal | D8: Pris i alt | F8: Pris / | G8: Antal | H8: Pris i alt
B9: enh. | F9: enh.
A10: Spindelfod kort | B10: 2.17
A11: BPF Fodsokkel | B11: 2.17 | E11: Diagonalstag 3.0 m | F11: 5.9
E12: Diagonalstag 1,6 m | F12: 5.9
A13: Strø / trykudligner | B13: =('2016'!B13*Faktor!$B$5)+'2016'!B13 -> 1.4353925
A15: FS 3,0 m Søjle | B15: 33.11 | E15: Traller 2.2 x 0.35m | F15: 4.16
A16: FS 2,0 m Søjle | B16: 22.08 | E16: Traller 2.2 x 0.5m | F16: 4.92
A17: FS 1,5 m Søjle | B17: 16.57 | E17: Kantbrædder | F17: 5.1
A18: FS 1.0 m Søjle | B18: 11.03 | E18: Låsejern | F18: 0.93
A19: FS 0,5 m Søjle | B19: 5.51
E20: Stiger til 3m | F20: 2.9
A21: LB 4,0 m bjælke | B21: 19.38
A22: LB 3,6 m bjælke | B22: 12.15
A23: LB 3,0 m bjælke | B23: 8.22 | E23: Koblinger fast | F23: 3.24
A24: LB 2,5 m bjælke | B24: 8.22 | E24: Koblinger dreje | F24: 3.24
A25: TB 1,9 m bjælke | B25: 4.92 | E25: Koblinger SK | F25: 3.24
A26: TB 1,6 m bjælke | B26: 4.92 | E26: Koblinger Kipfinger | F26: 3.24
A27: TB 1,2 m bjælke | B27: 4.92 | E27: Koblinger singel | F27: 3.24
A28: TB 1,0 m bjælke | B28: 4.92 | E28: Koblinger samler | F28: 3.24
A29: TB 0,5 m bjælke | B29: 4.92
E30: Net pr. m2 | F30: =('2016'!F30*Faktor!$B$5)+'2016'!F30 -> 2.3050098
A31: SKR 4.0 m rækværk | B31: 10.02 | E31: Plastik pr. m2 | F31: 5.56
A32: SKR 3.6 m rækværk | B32: 5.72
A33: SKR 3.0 m rækværk | B33: =('2016'!B33*Faktor!$B$5)+'2016'!B33 -> 2.8498303
A34: SKR 1.9 m rækværk | B34: =('2016'!B34*Faktor!$B$5)+'2016'!B34 -> 2.8498303
A35: SKR 1.6 m rækværk | B35: =('2016'!B35*Faktor!$B$5)+'2016'!B35 -> 2.8498303 | E35: Grønne skilte | F35: 5
A36: SKR 1.2 m rækværk | B36: =('2016'!B36*Faktor!$B$5)+'2016'!B36 -> 2.8498303 | E36: Reklameskilt | F36: =('2016'!F36*Faktor!$B$5)+'2016'!F36 -> 8.2454627
A37: SKR 1.0 m rækværk | B37: =('2016'!B37*Faktor!$B$5)+'2016'!B37 -> 2.8498303
A41: Bøjleanker | B41: 6.66 | E41: Montage pris
A42: Røranker | B42: 8.33 | E42: Demontage pris
E43: Luk af hul | F43: =('2016'!F43*Faktor!$B$5)+'2016'!F43 -> 2.7869664
A44: Stilladsrør 1M | B44: 4.47 | E44: Tillæg % +
A45: Stilladsrør 2M | B45: 8.94 | E45: Skur/Dyrtid | F45: 58.13
...

Sheet 2018
A1: HAKI 2018
A2: Sted | F2: Dato
A3: Opgave | F3: Mont
F4: Demo
A5: Kunde | F5: Montør
A6: Sag nr.
B8: Pris / | C8: Antal | D8: Pris i alt | F8: Pris / | G8: Antal | H8: Pris i alt
B9: enh. | F9: enh.
A10: Spindelfod kort | B10: =('2017'!B10*Faktor!$B$6)+'2017'!B10 -> 2.21123
A11: BPF Fodsokkel | B11: =('2017'!B11*Faktor!$B$6)+'2017'!B11 -> 2.21123 | E11: Diagonalstag 3.0 m | F11: =('2017'!F11*Faktor!$B$6)+'2017'!F11 -> 6.0121
E12: Diagonalstag 1,6 m | F12: =('2017'!F12*Faktor!$B$6)+'2017'!F12 -> 6.0121
A13: Strø / trykudligner | B13: 1.47
E14: Tralle løft
A15: FS 3,0 m Søjle | B15: =('2017'!B15*Faktor!$B$6)+'2017'!B15 -> 33.73909 | E15: Traller 2.2 x 0.35m | F15: =('2017'!F15*Faktor!$B$6)+'2017'!F15 -> 4.23904
A16: FS 2,0 m Søjle | B16: =('2017'!B16*Faktor!$B$6)+'2017'!B16 -> 22.49952 | E16: Traller 2.2 x 0.5m | F16: =('2017'!F16*Faktor!$B$6)+'2017'!F16 -> 5.01348
A17: FS 1,5 m Søjle | B17: =('2017'!B17*Faktor!$B$6)+'2017'!B17 -> 16.88483 | E17: Kantbrædder | F17: =('2017'!F17*Faktor!$B$6)+'2017'!F17 -> 5.1969
A18: FS 1.0 m Søjle | B18: =('2017'!B18*Faktor!$B$6)+'2017'!B18 -> 11.23957 | E18: Låsejern | F18: =('2017'!F18*Faktor!$B$6)+'2017'!F18 -> 0.94767
A19: FS 0,5 m Søjle | B19: =('2017'!B19*Faktor!$B$6)+'2017'!B19 -> 5.61469
E20: Stiger til 3m | F20: =('2017'!F20*Faktor!$B$6)+'2017'!F20 -> 2.9551
A21: LB 4,0 m bjælke | B21: =('2017'!B21*Faktor!$B$6)+'2017'!B21 -> 19.74822
A22: LB 3,6 m bjælke | B22: =('2017'!B22*Faktor!$B$6)+'2017'!B22 -> 12.38085
A23: LB 3,0 m bjælke | B23: =('2017'!B23*Faktor!$B$6)+'2017'!B23 -> 8.37618 | E23: Koblinger fast | F23: =('2017'!F23*Faktor!$B$6)+'2017'!F23 -> 3.30156
A24: LB 2,5 m bjælke | B24: =('2017'!B24*Faktor!$B$6)+'2017'!B24 -> 8.37618 | E24: Koblinger dreje | F24: =('2017'!F24*Faktor!$B$6)+'2017'!F24 -> 3.30156
A25: TB 1,9 m bjælke | B25: =('2017'!B25*Faktor!$B$6)+'2017'!B25 -> 5.01348 | E25: Koblinger SK | F25: =('2017'!F25*Faktor!$B$6)+'2017'!F25 -> 3.30156
A26: TB 1,6 m bjælke | B26: =('2017'!B26*Faktor!$B$6)+'2017'!B26 -> 5.01348 | E26: Koblinger Kipfinger | F26: =('2017'!F26*Faktor!$B$6)+'2017'!F26 -> 3.30156
A27: TB 1,2 m bjælke | B27: =('2017'!B27*Faktor!$B$6)+'2017'!B27 -> 5.01348 | E27: Koblinger singel | F27: =('2017'!F27*Faktor!$B$6)+'2017'!F27 -> 3.30156
A28: TB 1,0 m bjælke | B28: =('2017'!B28*Faktor!$B$6)+'2017'!B28 -> 5.01348 | E28: Koblinger samler | F28: =('2017'!F28*Faktor!$B$6)+'2017'!F28 -> 3.30156
A29: TB 0,5 m bjælke | B29: =('2017'!B29*Faktor!$B$6)+'2017'!B29 -> 5.01348
E30: Net pr. m2 | F30: =('2017'!F30*Faktor!$B$6)+'2017'!F30 -> 2.348805
A31: SKR 4.0 m rækværk | B31: =('2017'!B31*Faktor!$B$6)+'2017'!B31 -> 10.21038 | E31: Plastik pr. m2 | F31: =('2017'!F31*Faktor!$B$6)+'2017'!F31 -> 5.66564
A32: SKR 3.6 m rækværk | B32: =('2017'!B32*Faktor!$B$6)+'2017'!B32 -> 5.82868
A33: SKR 3.0 m rækværk | B33: =('2017'!B33*Faktor!$B$6)+'2017'!B33 -> 2.9039771 | E33: Dobbelt tværgelænder | F33: 5.15
A34: SKR 1.9 m rækværk | B34: =('2017'!B34*Faktor!$B$6)+'2017'!B34 -> 2.9039771
A35: SKR 1.6 m rækværk | B35: =('2017'!B35*Faktor!$B$6)+'2017'!B35 -> 2.9039771 | E35: Grønne skilte | F35: 5
A36: SKR 1.2 m rækværk | B36: =('2017'!B36*Faktor!$B$6)+'2017'!B36 -> 2.9039771 | E36: Reklameskilt | F36: 8.41
A37: SKR 1.0 m rækværk | B37: =('2017'!B37*Faktor!$B$6)+'2017'!B37 -> 2.9039771 | E37: Kegle uden fod | F37: 5.2
E38: Kegle med fod | F38: 8.54
E39: Geda hejs | F39: 250.6
E40: El hejs | F40: 126.57
A41: Bøjleanker | B41: =('2017'!B41*Faktor!$B$6)+'2017'!B41 -> 6.78654 | E41: Montage pris
...

Sheet 2019
A1: HAKI 2019
A2: Sted | F2: Dato
A3: Opgave | F3: Mont
F4: Demo
A5: Kunde | F5: Montør
A6: Sag nr.
B8: Pris / | C8: Antal | D8: Pris i alt | F8: Pris / | G8: Antal | H8: Pris i alt
B9: enh. | F9: enh.
A10: Spindelfod kort | B10: 2.25
A11: BPF Fodsokkel | B11: 2.25 | E11: Diagonalstag 3.0 m | F11: =('2018'!F11*Faktor!$B$7)+'2018'!F11 -> 6.1383541
E12: Diagonalstag 1,6 m | F12: =('2018'!F12*Faktor!$B$7)+'2018'!F12 -> 6.1383541
A13: Strø / trykudligner | B13: =('2018'!B13*Faktor!$B$7)+'2018'!B13 -> 1.50087
A15: FS 3,0 m Søjle | B15: =('2018'!B15*Faktor!$B$7)+'2018'!B15 -> 34.447611 | E15: Traller 2.2 x 0.35m | F15: =('2018'!F15*Faktor!$B$7)+'2018'!F15 -> 4.3280598
A16: FS 2,0 m Søjle | B16: =('2018'!B16*Faktor!$B$7)+'2018'!B16 -> 22.97201 | E16: Traller 2.2 x 0.5m | F16: =('2018'!F16*Faktor!$B$7)+'2018'!F16 -> 5.1187631
A17: FS 1,5 m Søjle | B17: =('2018'!B17*Faktor!$B$7)+'2018'!B17 -> 17.239411 | E17: Kantbrædder | F17: =('2018'!F17*Faktor!$B$7)+'2018'!F17 -> 5.3060349
A18: FS 1.0 m Søjle | B18: =('2018'!B18*Faktor!$B$7)+'2018'!B18 -> 11.475601 | E18: Låsejern | F18: =('2018'!F18*Faktor!$B$7)+'2018'!F18 -> 0.96757107
A19: FS 0,5 m Søjle | B19: =('2018'!B19*Faktor!$B$7)+'2018'!B19 -> 5.7325985
E20: Stiger til 3m | F20: =('2018'!F20*Faktor!$B$7)+'2018'!F20 -> 3.0171571
A21: LB 4,0 m bjælke | B21: =('2018'!B21*Faktor!$B$7)+'2018'!B21 -> 20.162933
A22: LB 3,6 m bjælke | B22: =('2018'!B22*Faktor!$B$7)+'2018'!B22 -> 12.640848
A23: LB 3,0 m bjælke | B23: =('2018'!B23*Faktor!$B$7)+'2018'!B23 -> 8.5520798 | E23: Koblinger fast | F23: =('2018'!F23*Faktor!$B$7)+'2018'!F23 -> 3.3708928
A24: LB 2,5 m bjælke | B24: =('2018'!B24*Faktor!$B$7)+'2018'!B24 -> 8.5520798 | E24: Koblinger dreje | F24: =('2018'!F24*Faktor!$B$7)+'2018'!F24 -> 3.3708928
A25: TB 1,9 m bjælke | B25: =('2018'!B25*Faktor!$B$7)+'2018'!B25 -> 5.1187631 | E25: Koblinger SK | F25: =('2018'!F25*Faktor!$B$7)+'2018'!F25 -> 3.3708928
A26: TB 1,6 m bjælke | B26: =('2018'!B26*Faktor!$B$7)+'2018'!B26 -> 5.1187631 | E26: Koblinger Kipfinger | F26: =('2018'!F26*Faktor!$B$7)+'2018'!F26 -> 3.3708928
A27: TB 1,2 m bjælke | B27: =('2018'!B27*Faktor!$B$7)+'2018'!B27 -> 5.1187631 | E27: Koblinger singel | F27: =('2018'!F27*Faktor!$B$7)+'2018'!F27 -> 3.3708928
A28: TB 1,0 m bjælke | B28: =('2018'!B28*Faktor!$B$7)+'2018'!B28 -> 5.1187631 | E28: Koblinger samler | F28: =('2018'!F28*Faktor!$B$7)+'2018'!F28 -> 3.3708928
A29: TB 0,5 m bjælke | B29: =('2018'!B29*Faktor!$B$7)+'2018'!B29 -> 5.1187631
E30: Net pr. m2 | F30: =('2018'!F30*Faktor!$B$7)+'2018'!F30 -> 2.3981299
A31: SKR 4.0 m rækværk | B31: =('2018'!B31*Faktor!$B$7)+'2018'!B31 -> 10.424798 | E31: Plastik pr. m2 | F31: =('2018'!F31*Faktor!$B$7)+'2018'!F31 -> 5.7846184
A32: SKR 3.6 m rækværk | B32: =('2018'!B32*Faktor!$B$7)+'2018'!B32 -> 5.9510823
A33: SKR 3.0 m rækværk | B33: =('2018'!B33*Faktor!$B$7)+'2018'!B33 -> 2.9649606 | E33: Dobbelt tværgelænder | F33: 5.15
A34: SKR 1.9 m rækværk | B34: =('2018'!B34*Faktor!$B$7)+'2018'!B34 -> 2.9649606
A35: SKR 1.6 m rækværk | B35: =('2018'!B35*Faktor!$B$7)+'2018'!B35 -> 2.9649606 | E35: Grønne skilte | F35: =('2018'!F35*Faktor!$B$7)+'2018'!F35 -> 5.105
A36: SKR 1.2 m rækværk | B36: =('2018'!B36*Faktor!$B$7)+'2018'!B36 -> 2.9649606 | E36: Reklameskilt | F36: =('2018'!F36*Faktor!$B$7)+'2018'!F36 -> 8.58661
A37: SKR 1.0 m rækværk | B37: =('2018'!B37*Faktor!$B$7)+'2018'!B37 -> 2.9649606 | E37: Kegle uden fod | F37: =('2018'!F37*Faktor!$B$7)+'2018'!F37 -> 5.3092
E38: Kegle med fod | F38: =('2018'!F38*Faktor!$B$7)+'2018'!F38 -> 8.71934
E39: Geda hejs | F39: =('2018'!F39*Faktor!$B$7)+'2018'!F39 -> 255.8626
E40: El hejs | F40: =('2018'!F40*Faktor!$B$7)+'2018'!F40 -> 129.22797
A41: Bøjleanker | B41: =('2018'!B41*Faktor!$B$7)+'2018'!B41 -> 6.9290573 | E41: Montage pris
A42: Røranker | B42: =('2018'!B42*Faktor!$B$7)+'2018'!B42 -> 8.6665237 | E42: Demontage pris
...

Sheet 2020
A1: HAKI 2020
A2: Sted | F2: Dato
A3: Opgave | F3: Mont
A4: Kunde | F4: Demo
A5: Sag nr. | F5: Montør
B8: Pris / | C8: Antal | D8: Pris i alt | F8: Pris / | G8: Antal | H8: Pris i alt
B9: enh. | F9: enh.
A10: Spindelfod kort | B10: 2.3
A11: BPF Fodsokkel | B11: =('2019'!B11*Faktor!$B$8)+'2019'!B11 -> 2.29725 | E11: Diagonalstag 3.0 m | F11: =('2019'!F11*Faktor!$B$7)+'2019'!F11 -> 6.2672595
E12: Diagonalstag 1,6 m | F12: =('2019'!F12*Faktor!$B$7)+'2019'!F12 -> 6.2672595
A13: Strø / trykudligner | B13: =('2019'!B13*Faktor!$B$8)+'2019'!B13 -> 1.5323883
A15: FS 3,0 m Søjle | B15: =('2019'!B15*Faktor!$B$8)+'2019'!B15 -> 35.171011 | E15: Traller 2.2 x 0.35m | F15: =('2019'!F15*Faktor!$B$7)+'2019'!F15 -> 4.4189491
A16: FS 2,0 m Søjle | B16: =('2019'!B16*Faktor!$B$8)+'2019'!B16 -> 23.454422 | E16: Traller 2.2 x 0.5m | F16: =('2019'!F16*Faktor!$B$7)+'2019'!F16 -> 5.2262571
A17: FS 1,5 m Søjle | B17: =('2019'!B17*Faktor!$B$8)+'2019'!B17 -> 17.601439 | E17: Kantbrædder | F17: =('2019'!F17*Faktor!$B$7)+'2019'!F17 -> 5.4174616
A18: FS 1.0 m Søjle | B18: =('2019'!B18*Faktor!$B$8)+'2019'!B18 -> 11.716589 | E18: Låsejern | F18: =('2019'!F18*Faktor!$B$7)+'2019'!F18 -> 0.98789006
A19: FS 0,5 m Søjle | B19: =('2019'!B19*Faktor!$B$8)+'2019'!B19 -> 5.8529831
E20: Stiger til 3m | F20: =('2019'!F20*Faktor!$B$7)+'2019'!F20 -> 3.0805174
A21: LB 4,0 m bjælke | B21: =('2019'!B21*Faktor!$B$8)+'2019'!B21 -> 20.586354
A22: LB 3,6 m bjælke | B22: =('2019'!B22*Faktor!$B$8)+'2019'!B22 -> 12.906306
A23: LB 3,0 m bjælke | B23: =('2019'!B23*Faktor!$B$8)+'2019'!B23 -> 8.7316735 | E23: Koblinger fast | F23: =('2019'!F23*Faktor!$B$7)+'2019'!F23 -> 3.4416815
A24: LB 2,5 m bjælke | B24: =('2019'!B24*Faktor!$B$8)+'2019'!B24 -> 8.7316735 | E24: Koblinger dreje | F24: =('2019'!F24*Faktor!$B$7)+'2019'!F24 -> 3.4416815
A25: TB 1,9 m bjælke | B25: =('2019'!B25*Faktor!$B$8)+'2019'!B25 -> 5.2262571 | E25: Koblinger SK | F25: =('2019'!F25*Faktor!$B$7)+'2019'!F25 -> 3.4416815
A26: TB 1,6 m bjælke | B26: =('2019'!B26*Faktor!$B$8)+'2019'!B26 -> 5.2262571 | E26: Koblinger Kipfinger | F26: =('2019'!F26*Faktor!$B$7)+'2019'!F26 -> 3.4416815
A27: TB 1,2 m bjælke | B27: =('2019'!B27*Faktor!$B$8)+'2019'!B27 -> 5.2262571 | E27: Koblinger singel | F27: =('2019'!F27*Faktor!$B$7)+'2019'!F27 -> 3.4416815
A28: TB 1,0 m bjælke | B28: =('2019'!B28*Faktor!$B$8)+'2019'!B28 -> 5.2262571 | E28: Koblinger samler | F28: =('2019'!F28*Faktor!$B$7)+'2019'!F28 -> 3.4416815
A29: TB 0,5 m bjælke | B29: =('2019'!B29*Faktor!$B$8)+'2019'!B29 -> 5.2262571
E30: Net pr. m2 | F30: =('2019'!F30*Faktor!$B$7)+'2019'!F30 -> 2.4484906
A31: SKR 4.0 m rækværk | B31: =('2019'!B31*Faktor!$B$8)+'2019'!B31 -> 10.643719 | E31: Plastik pr. m2 | F31: =('2019'!F31*Faktor!$B$7)+'2019'!F31 -> 5.9060954
A32: SKR 3.6 m rækværk | B32: =('2019'!B32*Faktor!$B$8)+'2019'!B32 -> 6.076055
A33: SKR 3.0 m rækværk | B33: =('2019'!B33*Faktor!$B$8)+'2019'!B33 -> 3.0272248 | E33: Dobbelt tværgelænder | F33: =('2019'!F33*Faktor!$B$7)+'2019'!F33 -> 5.25815
A34: SKR 1.9 m rækværk | B34: =('2019'!B34*Faktor!$B$8)+'2019'!B34 -> 3.0272248
A35: SKR 1.6 m rækværk | B35: =('2019'!B35*Faktor!$B$8)+'2019'!B35 -> 3.0272248 | E35: Grønne skilte | F35: =('2019'!F35*Faktor!$B$7)+'2019'!F35 -> 5.212205
A36: SKR 1.2 m rækværk | B36: =('2019'!B36*Faktor!$B$8)+'2019'!B36 -> 3.0272248 | E36: Reklameskilt | F36: =('2019'!F36*Faktor!$B$7)+'2019'!F36 -> 8.7669288
A37: SKR 1.0 m rækværk | B37: =('2019'!B37*Faktor!$B$8)+'2019'!B37 -> 3.0272248 | E37: Kegle uden fod | F37: =('2019'!F37*Faktor!$B$7)+'2019'!F37 -> 5.4206932
E38: Kegle med fod | F38: =('2019'!F38*Faktor!$B$7)+'2019'!F38 -> 8.9024461
E39: Geda hejs | F39: =('2019'!F39*Faktor!$B$7)+'2019'!F39 -> 261.23571
E40: El hejs | F40: =('2019'!F40*Faktor!$B$7)+'2019'!F40 -> 131.94176
A41: Bøjleanker | B41: =('2019'!B41*Faktor!$B$8)+'2019'!B41 -> 7.0745675 | E41: Montage pris
A42: Røranker | B42: =('2019'!B42*Faktor!$B$8)+'2019'!B42 -> 8.8485207 | E42: Demontage pris
E43: Luk af hul | F43: =('2019'!F43*Faktor!$B$7)+'2019'!F43 -> 2.9604477
...

Sheet 2021
A1: HAKI 2021
A2: Sted | F2: Dato
A3: Opgave | F3: Mont
A4: Kunde | F4: Demo
A5: Sag nr. | F5: Montør
B8: Pris / | C8: Antal | D8: Pris i alt | F8: Pris / | G8: Antal | H8: Pris i alt
B9: enh. | F9: enh.
A10: Spindelfod kort | B10: 2.36
A11: BPF Fodsokkel | B11: 2.36 | E11: Diagonalstag 3.0 m | F11: 6.4
E12: Diagonalstag 1,6 m | F12: 6.4
A13: Strø / trykudligner | B13: 1.56
A15: FS 3,0 m Søjle | B15: 35.91 | E15: Traller 2.2 x 0.35m | F15: =('2019'!F15*Faktor!$B$7)+'2019'!F15 -> 4.4189491
A16: FS 2,0 m Søjle | B16: 23.94 | E16: Traller 2.2 x 0.5m | F16: 5.34
A17: FS 1,5 m Søjle | B17: 17.97 | E17: Kantbrædder | F17: 5.53
A18: FS 1.0 m Søjle | B18: 11.97 | E18: Låsejern | F18: 1.01
A19: FS 0,5 m Søjle | B19: 5.97
E20: Stiger til 3m | F20: 3.98
E21: Skaktrør | F21: 34.32
E22: Tragt | F22: 63.17
A23: LB 3,0 m bjælke | B23: 8.91 | E23: Koblinger fast | F23: 3.51
A24: LB 2,5 m bjælke | B24: 8.91 | E24: Koblinger dreje | F24: 3.51
A25: TB 1,9 m bjælke | B25: 5.34 | E25: Koblinger SK | F25: 3.51
A26: TB 1,6 m bjælke | B26: 5.34 | E26: Koblinger Kipfinger | F26: 3.51
A27: TB 1,2 m bjælke | B27: 5.34 | E27: Koblinger singel | F27: 3.51
A28: TB 1,0 m bjælke | B28: 5.34 | E28: Koblinger samler | F28: 3.51
A29: TB 0,5 m bjælke | B29: 5.34
E30: Net pr. m2 | F30: 2.5
E31: Plastik pr. m2 | F31: 6.03
A33: SKR 3.0 m rækværk | B33: 3.1 | E33: Dobbelt tværgelænder | F33: 5.46
A34: SKR 1.9 m rækværk | B34: 3.1
A35: SKR 1.6 m rækværk | B35: 3.1 | E35: Grønne skilte | F35: 5
A36: SKR 1.2 m rækværk | B36: 3.1 | E36: Reklameskilt | F36: =('2019'!F36*Faktor!$B$7)+'2019'!F36 -> 8.7669288
A37: SKR 1.0 m rækværk | B37: 3.1 | E37: Kegle uden fod | F37: =('2019'!F37*Faktor!$B$7)+'2019'!F37 -> 5.4206932
A38: Trappeløb | B38: 45.17 | E38: Kegle med fod | F38: 9.09
A39: Trappe gelænder | B39: 11.3 | E39: Geda hejs | F39: 266.73
E40: El hejs | F40: 134.71
A41: Bøjleanker | B41: 7.22 | E41: Montage pris
A42: Røranker | B42: 9.04 | E42: Demontage pris
E43: Luk af hul | F43: 3.02
A44: Stilladsrør 1M | B44: 4.85 | E44: Tillæg % +
...

Sheet 2022
A1: HAKI 2023
A2: Sted | F2: Dato
A3: Opgave | F3: Mont
A4: Kunde | F4: Demo
A5: Sag nr. | F5: Montør
B8: Pris / | C8: Antal | D8: Pris i alt | F8: Pris / | G8: Antal | H8: Pris i alt
B9: enh. | F9: enh.
A10: Spindelfod kort | B10: 2.5
A11: BPF Fodsokkel | B11: 2.93 | E11: Diagonalstag 3.0 m | F11: 8.78
E12: Diagonalstag 1,6 m | F12: 8.78
A13: Strø / trykudligner | B13: 1.66
E14: Traller 2.2 x 0.35m | F14: 9.76
A15: FS 3,0 m Søjle | B15: 23.43 | E15: Traller 2.2 x 0.5m | F15: 13.66
A16: FS 2,0 m Søjle | B16: 15.62 | E16: Traller 2,2 x 0,5m alu | F16: 9.76
A17: FS 1,5 m Søjle | B17: 11.72 | E17: Kantbrædder | F17: 8.78
A18: FS 1.0 m Søjle | B18: 7.81 | E18: Låsejern | F18: 1.06
A19: FS 0,5 m Søjle | B19: 3.91
E20: Stiger til 3m | F20: 4.21
A21: LB 3,0 m bjælke | B21: 8.78 | E21: Skaktrør | F21: 36.43
A22: LB 2,5 m bjælke | B22: 5.85 | E22: Tragt | F22: 36.43
A23: TB 1,9 m bjælke | B23: 5.85 | E23: Koblinger fast | F23: 3.73
A24: TB 1,6 m bjælke | B24: 5.85 | E24: Koblinger dreje | F24: 3.73
A25: TB 1,2 m bjælke | B25: 4.88 | E25: Koblinger SK | F25: 3.73
A26: TB 1,0 m bjælke | B26: 4.88 | E26: Koblinger Kipfinger | F26: 3.73
A27: TB 0,5 m bjælke | B27: 4.88 | E27: Koblinger singel | F27: 3.73
E28: Koblinger samler | F28: 3.73
A29: Net pr. m2 | B29: 2.66
A30: Plastik pr. m2 | B30: 6.39 | E30: Dobbelt tværgelænder | F30: 5.85
E32: Grønne skilte | F32: 5
A33: SKR 3.0 m rækværk | B33: 4.39 | E33: Reklameskilt | F33: 9.09
A34: SKR 1.9 m rækværk | B34: 2.93 | E34: Kegle uden fod | F34: 5.74
A35: SKR 1.6 m rækværk | B35: 2.93 | E35: Kegle med fod | F35: 9.66
A36: SKR 1.2 m rækværk | B36: 2.44 | E36: Bræt | F36: 5.86
A37: SKR 1.0 m rækværk | B37: 2.44 | E37: Geda hejs | F37: 283.21
A38: Trappeløb | B38: 47.96 | E38: El hejs | F38: 142.04
A39: Trappe gelænder | B39: 12.51
E40: Huller | F40: 4.39
A41: Bøjleanker | B41: 13.66 | E41: Montage pris
A42: Røranker alu | B42: 13.66 | E42: Demontage pris
A43: Røranker stål | B43: 17.56 | E43: Luk af hul | F43: 3.22
...

Sheet 2023
A1: HAKI 2023
A2: Sted | F2: Dato
A3: Opgave | F3: Mont
A4: Kunde | F4: Demo
A5: Sag nr. | F5: Montør
B8: Pris / | C8: Antal | D8: Pris i alt | F8: Pris / | G8: Antal | H8: Pris i alt
B9: enh. | F9: enh.
A10: Spindelfod kort | B10: 2.5
A11: BPF Fodsokkel | B11: 2.93 | E11: Diagonalstag 3.0 m | F11: 8.78
E12: Diagonalstag 1,6 m | F12: 8.78
A13: Strø / trykudligner | B13: 1.66
E14: Traller 2.2 x 0.35m | F14: 9.76
A15: FS 3,0 m Søjle | B15: 23.43 | E15: Traller 2.2 x 0.5m | F15: 13.66
A16: FS 2,0 m Søjle | B16: 15.62 | E16: Traller 2,2 x 0,5m alu | F16: 9.76
A17: FS 1,5 m Søjle | B17: 11.72 | E17: Kantbrædder | F17: 8.78
A18: FS 1.0 m Søjle | B18: 7.81 | E18: Låsejern | F18: 1.06
A19: FS 0,5 m Søjle | B19: 3.91
E20: Stiger til 3m | F20: 4.21
A21: LB 3,0 m bjælke | B21: 8.78 | E21: Skaktrør | F21: 36.43
A22: LB 2,5 m bjælke | B22: 5.85 | E22: Tragt | F22: 36.43
A23: TB 1,9 m bjælke | B23: 5.85 | E23: Koblinger fast | F23: 3.73
A24: TB 1,6 m bjælke | B24: 5.85 | E24: Koblinger dreje | F24: 3.73
A25: TB 1,2 m bjælke | B25: 4.88 | E25: Koblinger SK | F25: 3.73
A26: TB 1,0 m bjælke | B26: 4.88 | E26: Koblinger Kipfinger | F26: 3.73
A27: TB 0,5 m bjælke | B27: 4.88 | E27: Koblinger singel | F27: 3.73
E28: Koblinger samler | F28: 3.73
A29: Net pr. m2 | B29: 2.66
A30: Plastik pr. m2 | B30: 6.39 | E30: Dobbelt tværgelænder | F30: 5.85
E32: Grønne skilte | F32: 5
A33: SKR 3.0 m rækværk | B33: 4.39 | E33: Reklameskilt | F33: 9.09
A34: SKR 1.9 m rækværk | B34: 2.93 | E34: Kegle uden fod | F34: 5.74
A35: SKR 1.6 m rækværk | B35: 2.93 | E35: Kegle med fod | F35: 9.66
A36: SKR 1.2 m rækværk | B36: 2.44 | E36: Bræt | F36: 5.86
A37: SKR 1.0 m rækværk | B37: 2.44 | E37: Geda hejs | F37: 283.21
A38: Trappeløb | B38: 47.96 | E38: El hejs | F38: 142.04
A39: Trappe gelænder | B39: 12.51
E40: Huller | F40: 4.39
A41: Bøjleanker | B41: 13.66 | E41: Montage pris
A42: Røranker alu | B42: 13.66 | E42: Demontage pris
A43: Røranker stål | B43: 17.56 | E43: Luk af hul | F43: 3.22
...

Sheet 2025
A1: HAKI 2025
A2: Sted | F2: Dato
A3: Opgave | F3: Mont
A4: Kunde | F4: Demo
A5: Sag nr. | F5: Montør
B8: Pris / | C8: Antal | D8: Pris i alt | F8: Pris / | G8: Antal | H8: Pris i alt
B9: enh. | F9: enh.
A10: Spindelfod kort | B10: 2.68
A11: BPF Fodsokkel | B11: =('2023'!B11/100)*103.9 -> 3.04427 | E11: Diagonalstag 3.0 m | F11: 9.4
E12: Diagonalstag 1,6 m | F12: 9.4
A13: Strø / trykudligner | B13: 1.77
E14: Traller 2.2 x 0.35m | F14: 10.44
A15: FS 3,0 m Søjle | B15: 25.05 | E15: Traller 2.2 x 0.5m | F15: 14.62
A16: FS 2,0 m Søjle | B16: 16.7 | E16: Traller 2,2 x 0,5m alu | F16: 10.44
A17: FS 1,5 m Søjle | B17: 12.53 | E17: Kantbrædder | F17: 9.4
A18: FS 1.0 m Søjle | B18: 8.35 | E18: Låsejern | F18: 1.14
A19: FS 0,5 m Søjle | B19: 4.18
E20: Stiger til 3m | F20: 4.51
A21: LB 3,0 m bjælke | B21: 17.75 | E21: Skaktrør | F21: 38.99
A22: LB 2,5 m bjælke | B22: 16.71 | E22: Tragt | F22: 38.99
A23: TB 1,9 m bjælke | B23: 6.26 | E23: Koblinger fast | F23: 3.99
A24: TB 1,6 m bjælke | B24: 6.26 | E24: Koblinger dreje | F24: 3.99
A25: TB 1,2 m bjælke | B25: 5.22 | E25: Koblinger SK | F25: 3.99
A26: TB 1,0 m bjælke | B26: 5.22 | E26: Koblinger Kipfinger | F26: 3.99
A27: TB 0,5 m bjælke | B27: 5.22 | E27: Koblinger singel | F27: 3.99
E28: Koblinger samler | F28: 3.99
A29: Net pr. m2 | B29: 2.85
A30: Plastik pr. m2 | B30: 6.84 | E30: Dobbelt tværgelænder | F30: 6.26
E32: Grønne skilte | F32: 5.15
A33: SKR 3.0 m rækværk | B33: 5.22 | E33: Reklameskilt | F33: 9.73
A34: SKR 1.9 m rækværk | B34: 3.92 | E34: Kegle uden fod | F34: 6.15
A35: SKR 1.6 m rækværk | B35: 3.92 | E35: Kegle med fod | F35: 10.33
A36: SKR 1.2 m rækværk | B36: 3.13 | E36: Bræt | F36: 6.28
A37: SKR 1.0 m rækværk | B37: 3.13 | E37: Geda hejs | F37: 303.08
A38: Trappeløb | B38: 51.35 | E38: El hejs | F38: 153.07
A39: Trappe gelænder | B39: 13.39
A41: Bøjleanker | B41: 14.62
A42: Røranker alu | B42: 14.62
A43: Røranker stål | B43: 18.79 | E43: Montagepris
E44: Demontagepris
...
