Workbook

Sheet Faktor
A1: Forøgelses faktor
A3: 2015 | B3: 0.014
A4: 2016 | B4: 0.019
A5: 2017 | B5: 0.014
A6: 2018 | B6: 0.019
A7: 2019 | B7: 0.018
A8: 2020 | B8: 0.021
A9: 2021 | B9: 0.021
A10: 2022 | B10: 0.021

Sheet 2014
D1: MODEX
A2: Sted | E2: Dato
A3: Opgave | E3: Mont.
A4: Kunde | E4: Demo.
A5: Sag nr. | E5: Montør
B6: Pris | C6: Antal | D6: I alt | F6: Pris | G6: Antal | H6: I alt
A7: Spindelfod | B7: 2.06 | E7: Profildæk 32/300 | F7: 3.95
A8: Begynderstykke | B8: 2.64 | E8: Profildæk 32/250 | F8: 3.95
A9: Vertikalstander 300 | B9: 31.48 | E9: Profildæk 32/200 | F9: 3.95
A10: Vertikalstander 200 | B10: 20.99 | E10: Profildæk 32/150 | F10: 1.97
A11: Vertikalstander 150 | B11: 15.75 | E11: Profildæk 32/125 | F11: 1.97
A12: Vertikalstander 100 | B12: 10.49 | E12: Profildæk 32/74 | F12: 1.97
E13: Stigedæk | F13: 7.91
A14: Horisontalrør 300 | B14: 4.68 | E14: Profildæk 70/300 | F14: 7.91
A15: Horisontalrør 250 | B15: 4.68 | E15: Profildæk 70/250 | F15: 7.91
A16: Horisontalrør 200 | B16: 4.68 | E16: Profildæk 70/200 | F16: 7.91
A17: Horisontalrør 150 | B17: 4.68 | E17: Profildæk 70/150 | F17: 3.95
A18: Horisontalrør 125 | B18: 4.68 | E18: Profildæk 70/125 | F18: 3.95
A19: Horisontalrør 113 | B19: 4.68 | E19: Profildæk 70/70 | F19: 3.95
A20: Horisontalrør 74 | B20: 4.68
A21: U-profil 300 | B21: 6.76 | E21: Stilladsrør 1M | F21: 4.25
A22: U-profil 250 | B22: 6.76 | E22: Stilladsrør 2M | F22: 8.5
A23: U-profil 200 | B23: 6.76 | E23: Stilladsrør 3M | F23: 12.75
A24: U-profil 150 | B24: 6.76 | E24: Stilladsrør 4M | F24: 17
A25: U-profil 113 | B25: 6.76 | E25: Stilladsrør 5M | F25: 21.25
A26: Løftesikring 113 | B26: 2.66 | E26: Stilladsrør 6M | F26: 25.5
A27: Løftesikring 150 | B27: 2.66
A28: Diagonal 200/300 | B28: 5.61
A29: Diagonal 200/250 | B29: 5.61
A30: Diagonal 200/200 | B30: 5.61 | E30: Klodæk 300/70 | F30: 4.84
A31: Diagonal 200/150 | B31: 5.61 | E31: Klodæk 250/70 | F31: 4.84
A32: Diagonal 200/113 | B32: 5.61 | E32: Alutrappe 2m | F32: 39.08
A33: Fodspark 300 | B33: 4.78 | E33: Gelænder til trappe | F33: 9.77
A34: Fodspark 250 | B34: 4.78
A35: Fodspark 200 | B35: 4.78
A36: Fodspark 150 | B36: 4.78 | E36: Koblinger fast | F36: 3.08
A37: Fodspark 125 | B37: 4.78 | E37: Koblinger dreje | F37: 3.08
E38: Koblinger SK | F38: 3.08
E39: Koblinger Kipfinger | F39: 3.08
A40: Bøjleanker | B40: 6.33 | E40: Koblinger singel | F40: 3.08
...

Sheet 2015
D1: MODEX
A2: Sted | E2: Dato
A3: Opgave | E3: Mont.
A4: Kunde | E4: Demo.
A5: Sag nr. | E5: Montør
B6: Pris | C6: Antal | D6: I alt | F6: Pris | G6: Antal | H6: I alt
A7: Spindelfod | B7: =('2014'!B7*Faktor!$B$3)+'2014'!B7 -> 2.08884 | E7: Profildæk 32/300 | F7: =('2014'!F7*Faktor!$B$3)+'2014'!F7 -> 4.0053
A8: Begynderstykke | B8: =('2014'!B8*Faktor!$B$3)+'2014'!B8 -> 2.67696 | E8: Profildæk 32/250 | F8: =('2014'!F8*Faktor!$B$3)+'2014'!F8 -> 4.0053
A9: Vertikalstander 300 | B9: =('2014'!B9*Faktor!$B$3)+'2014'!B9 -> 31.92072 | E9: Profildæk 32/200 | F9: =('2014'!F9*Faktor!$B$3)+'2014'!F9 -> 4.0053
A10: Vertikalstander 200 | B10: =('2014'!B10*Faktor!$B$3)+'2014'!B10 -> 21.28386 | E10: Profildæk 32/150 | F10: =('2014'!F10*Faktor!$B$3)+'2014'!F10 -> 1.99758
A11: Vertikalstander 150 | B11: =('2014'!B11*Faktor!$B$3)+'2014'!B11 -> 15.9705 | E11: Profildæk 32/125 | F11: =('2014'!F11*Faktor!$B$3)+'2014'!F11 -> 1.99758
A12: Vertikalstander 100 | B12: =('2014'!B12*Faktor!$B$3)+'2014'!B12 -> 10.63686 | E12: Profildæk 32/74 | F12: =('2014'!F12*Faktor!$B$3)+'2014'!F12 -> 1.99758
E13: Stigedæk | F13: =('2014'!F13*Faktor!$B$3)+'2014'!F13 -> 8.02074
A14: Horisontalrør 300 | B14: =('2014'!B14*Faktor!$B$3)+'2014'!B14 -> 4.74552 | E14: Profildæk 70/300 | F14: =('2014'!F14*Faktor!$B$3)+'2014'!F14 -> 8.02074
A15: Horisontalrør 250 | B15: =('2014'!B15*Faktor!$B$3)+'2014'!B15 -> 4.74552 | E15: Profildæk 70/250 | F15: =('2014'!F15*Faktor!$B$3)+'2014'!F15 -> 8.02074
A16: Horisontalrør 200 | B16: =('2014'!B16*Faktor!$B$3)+'2014'!B16 -> 4.74552 | E16: Profildæk 70/200 | F16: =('2014'!F16*Faktor!$B$3)+'2014'!F16 -> 8.02074
A17: Horisontalrør 150 | B17: =('2014'!B17*Faktor!$B$3)+'2014'!B17 -> 4.74552 | E17: Profildæk 70/150 | F17: =('2014'!F17*Faktor!$B$3)+'2014'!F17 -> 4.0053
A18: Horisontalrør 125 | B18: =('2014'!B18*Faktor!$B$3)+'2014'!B18 -> 4.74552 | E18: Profildæk 70/125 | F18: =('2014'!F18*Faktor!$B$3)+'2014'!F18 -> 4.0053
A19: Horisontalrør 113 | B19: =('2014'!B19*Faktor!$B$3)+'2014'!B19 -> 4.74552 | E19: Profildæk 70/70 | F19: =('2014'!F19*Faktor!$B$3)+'2014'!F19 -> 4.0053
A20: Horisontalrør 74 | B20: =('2014'!B20*Faktor!$B$3)+'2014'!B20 -> 4.74552
A21: U-profil 300 | B21: =('2014'!B21*Faktor!$B$3)+'2014'!B21 -> 6.85464 | E21: Stilladsrør 1M | F21: =('2014'!F21*Faktor!$B$3)+'2014'!F21 -> 4.3095
A22: U-profil 250 | B22: =('2014'!B22*Faktor!$B$3)+'2014'!B22 -> 6.85464 | E22: Stilladsrør 2M | F22: =('2014'!F22*Faktor!$B$3)+'2014'!F22 -> 8.619
A23: U-profil 200 | B23: =('2014'!B23*Faktor!$B$3)+'2014'!B23 -> 6.85464 | E23: Stilladsrør 3M | F23: =('2014'!F23*Faktor!$B$3)+'2014'!F23 -> 12.9285
A24: U-profil 150 | B24: =('2014'!B24*Faktor!$B$3)+'2014'!B24 -> 6.85464 | E24: Stilladsrør 4M | F24: =('2014'!F24*Faktor!$B$3)+'2014'!F24 -> 17.238
A25: U-profil 113 | B25: =('2014'!B25*Faktor!$B$3)+'2014'!B25 -> 6.85464 | E25: Stilladsrør 5M | F25: =('2014'!F25*Faktor!$B$3)+'2014'!F25 -> 21.5475
A26: Løftesikring 113 | B26: =('2014'!B26*Faktor!$B$3)+'2014'!B26 -> 2.69724 | E26: Stilladsrør 6M | F26: =('2014'!F26*Faktor!$B$3)+'2014'!F26 -> 25.857
A27: Løftesikring 150 | B27: =('2014'!B27*Faktor!$B$3)+'2014'!B27 -> 2.69724
A28: Diagonal 200/300 | B28: =('2014'!B28*Faktor!$B$3)+'2014'!B28 -> 5.68854
A29: Diagonal 200/250 | B29: =('2014'!B29*Faktor!$B$3)+'2014'!B29 -> 5.68854
A30: Diagonal 200/200 | B30: =('2014'!B30*Faktor!$B$3)+'2014'!B30 -> 5.68854 | E30: Klodæk 300/70 | F30: =('2014'!F30*Faktor!$B$3)+'2014'!F30 -> 4.90776
A31: Diagonal 200/150 | B31: =('2014'!B31*Faktor!$B$3)+'2014'!B31 -> 5.68854 | E31: Klodæk 250/70 | F31: =('2014'!F31*Faktor!$B$3)+'2014'!F31 -> 4.90776
A32: Diagonal 200/113 | B32: =('2014'!B32*Faktor!$B$3)+'2014'!B32 -> 5.68854 | E32: Alutrappe 2m | F32: =('2014'!F32*Faktor!$B$3)+'2014'!F32 -> 39.62712
A33: Fodspark 300 | B33: =('2014'!B33*Faktor!$B$3)+'2014'!B33 -> 4.84692 | E33: Gelænder til trappe | F33: =('2014'!F33*Faktor!$B$3)+'2014'!F33 -> 9.90678
A34: Fodspark 250 | B34: =('2014'!B34*Faktor!$B$3)+'2014'!B34 -> 4.84692
A35: Fodspark 200 | B35: =('2014'!B35*Faktor!$B$3)+'2014'!B35 -> 4.84692
A36: Fodspark 150 | B36: =('2014'!B36*Faktor!$B$3)+'2014'!B36 -> 4.84692 | E36: Koblinger fast | F36: =('2014'!F36*Faktor!$B$3)+'2014'!F36 -> 3.12312
A37: Fodspark 125 | B37: =('2014'!B37*Faktor!$B$3)+'2014'!B37 -> 4.84692 | E37: Koblinger dreje | F37: =('2014'!F37*Faktor!$B$3)+'2014'!F37 -> 3.12312
E38: Koblinger SK | F38: =('2014'!F38*Faktor!$B$3)+'2014'!F38 -> 3.12312
E39: Koblinger Kipfinger | F39: =('2014'!F39*Faktor!$B$3)+'2014'!F39 -> 3.12312
A40: Bøjleanker | B40: =('2014'!B40*Faktor!$B$3)+'2014'!B40 -> 6.41862 | E40: Koblinger singel | F40: =('2014'!F40*Faktor!$B$3)+'2014'!F40 -> 3.12312
...

Sheet 2016
A1: MODEX 2016
A2: Sted | E2: Dato
A3: Opgave | E3: Mont.
A4: Kunde | E4: Demo.
A5: Sag nr. | E5: Montør
B6: Pris | C6: Antal | D6: I alt | F6: Pris | G6: Antal | H6: I alt
A7: Spindelfod | B7: =('2015'!B7*Faktor!$B$4)+'2015'!B7 -> 2.128528 | E7: Profildæk 32/300 | F7: =('2015'!F7*Faktor!$B$4)+'2015'!F7 -> 4.0814007
A8: Begynderstykke | B8: =('2015'!B8*Faktor!$B$4)+'2015'!B8 -> 2.7278222 | E8: Profildæk 32/250 | F8: =('2015'!F8*Faktor!$B$4)+'2015'!F8 -> 4.0814007
A9: Vertikalstander 300 | B9: =('2015'!B9*Faktor!$B$4)+'2015'!B9 -> 32.527214 | E9: Profildæk 32/200 | F9: =('2015'!F9*Faktor!$B$4)+'2015'!F9 -> 4.0814007
A10: Vertikalstander 200 | B10: =('2015'!B10*Faktor!$B$4)+'2015'!B10 -> 21.688253 | E10: Profildæk 32/150 | F10: =('2015'!F10*Faktor!$B$4)+'2015'!F10 -> 2.035534
A11: Vertikalstander 150 | B11: =('2015'!B11*Faktor!$B$4)+'2015'!B11 -> 16.27394 | E11: Profildæk 32/125 | F11: =('2015'!F11*Faktor!$B$4)+'2015'!F11 -> 2.035534
A12: Vertikalstander 100 | B12: =('2015'!B12*Faktor!$B$4)+'2015'!B12 -> 10.83896 | E12: Profildæk 32/74 | F12: =('2015'!F12*Faktor!$B$4)+'2015'!F12 -> 2.035534
E13: Stigedæk | F13: 8.04
A14: Horisontalrør 300 | B14: =('2015'!B14*Faktor!$B$4)+'2015'!B14 -> 4.8356849 | E14: Profildæk 70/300 | F14: 5.07
A15: Horisontalrør 250 | B15: =('2015'!B15*Faktor!$B$4)+'2015'!B15 -> 4.8356849 | E15: Profildæk 70/250 | F15: 5.07
A16: Horisontalrør 200 | B16: =('2015'!B16*Faktor!$B$4)+'2015'!B16 -> 4.8356849 | E16: Profildæk 70/200 | F16: 5.07
A17: Horisontalrør 150 | B17: =('2015'!B17*Faktor!$B$4)+'2015'!B17 -> 4.8356849 | E17: Profildæk 70/150 | F17: 5.07
A18: Horisontalrør 125 | B18: =('2015'!B18*Faktor!$B$4)+'2015'!B18 -> 4.8356849 | E18: Profildæk 70/125 | F18: 5.07
A19: Horisontalrør 113 | B19: =('2015'!B19*Faktor!$B$4)+'2015'!B19 -> 4.8356849 | E19: Profildæk 70/70 | F19: 5.07
A20: Horisontalrør 74 | B20: =('2015'!B20*Faktor!$B$4)+'2015'!B20 -> 4.8356849
A21: U-profil 300 | B21: =('2015'!B21*Faktor!$B$4)+'2015'!B21 -> 6.9848782 | E21: Stilladsrør 1M | F21: =('2015'!F21*Faktor!$B$4)+'2015'!F21 -> 4.3913805
A22: U-profil 250 | B22: =('2015'!B22*Faktor!$B$4)+'2015'!B22 -> 6.9848782 | E22: Stilladsrør 2M | F22: =('2015'!F22*Faktor!$B$4)+'2015'!F22 -> 8.782761
A23: U-profil 200 | B23: =('2015'!B23*Faktor!$B$4)+'2015'!B23 -> 6.9848782 | E23: Stilladsrør 3M | F23: =('2015'!F23*Faktor!$B$4)+'2015'!F23 -> 13.174141
A24: U-profil 150 | B24: =('2015'!B24*Faktor!$B$4)+'2015'!B24 -> 6.9848782 | E24: Stilladsrør 4M | F24: =('2015'!F24*Faktor!$B$4)+'2015'!F24 -> 17.565522
A25: U-profil 113 | B25: =('2015'!B25*Faktor!$B$4)+'2015'!B25 -> 6.9848782 | E25: Stilladsrør 5M | F25: =('2015'!F25*Faktor!$B$4)+'2015'!F25 -> 21.956902
A26: Løftesikring 113 | B26: =('2015'!B26*Faktor!$B$4)+'2015'!B26 -> 2.7484876 | E26: Stilladsrør 6M | F26: =('2015'!F26*Faktor!$B$4)+'2015'!F26 -> 26.348283
A27: Løftesikring 150 | B27: =('2015'!B27*Faktor!$B$4)+'2015'!B27 -> 2.7484876
A28: Diagonal 200/300 | B28: =('2015'!B28*Faktor!$B$4)+'2015'!B28 -> 5.7966223
A29: Diagonal 200/250 | B29: =('2015'!B29*Faktor!$B$4)+'2015'!B29 -> 5.7966223
A30: Diagonal 200/200 | B30: =('2015'!B30*Faktor!$B$4)+'2015'!B30 -> 5.7966223 | E30: Klodæk 300/70 | F30: 5.07
A31: Diagonal 200/150 | B31: =('2015'!B31*Faktor!$B$4)+'2015'!B31 -> 5.7966223 | E31: Klodæk 250/70 | F31: 5.07
A32: Diagonal 200/113 | B32: =('2015'!B32*Faktor!$B$4)+'2015'!B32 -> 5.7966223 | E32: Alutrappe 2m | F32: =('2015'!F32*Faktor!$B$4)+'2015'!F32 -> 40.380035
A33: Fodspark 300 | B33: =('2015'!B33*Faktor!$B$4)+'2015'!B33 -> 4.9390115 | E33: Gelænder til trappe | F33: =('2015'!F33*Faktor!$B$4)+'2015'!F33 -> 10.095009
A34: Fodspark 250 | B34: =('2015'!B34*Faktor!$B$4)+'2015'!B34 -> 4.9390115
A35: Fodspark 200 | B35: =('2015'!B35*Faktor!$B$4)+'2015'!B35 -> 4.9390115
A36: Fodspark 150 | B36: =('2015'!B36*Faktor!$B$4)+'2015'!B36 -> 4.9390115 | E36: Koblinger fast | F36: =('2015'!F36*Faktor!$B$4)+'2015'!F36 -> 3.1824593
A37: Fodspark 125 | B37: =('2015'!B37*Faktor!$B$4)+'2015'!B37 -> 4.9390115 | E37: Koblinger dreje | F37: =('2015'!F37*Faktor!$B$4)+'2015'!F37 -> 3.1824593
E38: Koblinger SK | F38: =('2015'!F38*Faktor!$B$4)+'2015'!F38 -> 3.1824593
E39: Koblinger Kipfinger | F39: =('2015'!F39*Faktor!$B$4)+'2015'!F39 -> 3.1824593
A40: Bøjleanker | B40: =('2015'!B40*Faktor!$B$4)+'2015'!B40 -> 6.5405738 | E40: Koblinger singel | F40: =('2015'!F40*Faktor!$B$4)+'2015'!F40 -> 3.1824593
...

Sheet 2017
A1: MODEX 2017
A2: Sted | E2: Dato
A3: Opgave | E3: Mont.
A4: Kunde | E4: Demo.
A5: Sag nr. | E5: Montør
B6: Pris | C6: Antal | D6: I alt | F6: Pris | G6: Antal | H6: I alt
A7: Spindelfod | B7: 2.17 | E7: Profildæk 32/300 | F7: 4.16
A8: Begynderstykke | B8: 5.51 | E8: Profildæk 32/250 | F8: 4.16
A9: Vertikalstander 300 | B9: 33.11 | E9: Profildæk 32/200 | F9: 4.16
A10: Vertikalstander 200 | B10: 22.08 | E10: Profildæk 32/150 | F10: 2.07
A11: Vertikalstander 150 | B11: 16.57 | E11: Profildæk 32/125 | F11: 2.07
A12: Vertikalstander 100 | B12: 11.03 | E12: Profildæk 32/74 | F12: 2.07
E13: Stigedæk | F13: 8.18
A14: Horisontalrør 300 | B14: 4.92 | E14: Profildæk 70/300 | F14: 4.82
A15: Horisontalrør 250 | B15: 4.92 | E15: Profildæk 70/250 | F15: 3.99
A16: Horisontalrør 200 | B16: 4.92 | E16: Profildæk 70/200 | F16: 3.2
A17: Horisontalrør 150 | B17: 4.92 | E17: Profildæk 70/150 | F17: 2.39
A18: Horisontalrør 125 | B18: 4.92 | E18: Profildæk 70/125 | F18: 2.01
A19: Horisontalrør 113 | B19: 4.92 | E19: Profildæk 70/70 | F19: 1.14
A20: Horisontalrør 74 | B20: 4.92
A21: U-profil 300 | B21: 4.92 | E21: Stilladsrør 1M | F21: 4.47
A22: U-profil 250 | B22: 4.92 | E22: Stilladsrør 2M | F22: 8.94
A23: U-profil 200 | B23: 4.92 | E23: Stilladsrør 3M | F23: 13.41
A24: U-profil 150 | B24: 4.92 | E24: Stilladsrør 4M | F24: 17.88
A25: U-profil 113 | B25: 4.92 | E25: Stilladsrør 5M | F25: 22.35
A26: Løftesikring 113 | B26: =('2016'!B26*Faktor!$B$5)+'2016'!B26 -> 2.7869664 | E26: Stilladsrør 6M | F26: 26.82
A27: Løftesikring 150 | B27: =('2016'!B27*Faktor!$B$5)+'2016'!B27 -> 2.7869664
A28: Diagonal 200/300 | B28: 5.9
A29: Diagonal 200/250 | B29: 5.9
A30: Diagonal 200/200 | B30: 5.9 | E30: Klodæk 300/70 | F30: 4.82
A31: Diagonal 200/150 | B31: 5.9 | E31: Klodæk 250/70 | F31: 3.99
A32: Diagonal 200/113 | B32: 5.9 | E32: Alutrappe 2m | F32: 41.65
A33: Fodspark 300 | B33: 5.1 | E33: Gelænder til trappe | F33: 10.42
A34: Fodspark 250 | B34: 5.1
A35: Fodspark 200 | B35: 5.1
A36: Fodspark 150 | B36: 5.1 | E36: Koblinger fast | F36: 3.24
A37: Fodspark 125 | B37: 5.1 | E37: Koblinger dreje | F37: 3.24
E38: Koblinger SK | F38: 3.24
E39: Koblinger Kipfinger | F39: 3.24
A40: Bøjleanker | B40: 6.66 | E40: Koblinger singel | F40: 3.24
...

Sheet 2018
A1: MODEX 2018
A2: Sted | E2: Dato
A3: Opgave | E3: Mont.
A4: Kunde | E4: Demo.
A5: Sag nr. | E5: Montør
B6: Pris | C6: Antal | D6: I alt | F6: Pris | G6: Antal | H6: I alt
A7: Spindelfod | B7: =('2017'!B7*Faktor!$B$6)+'2017'!B7 -> 2.21123 | E7: Profildæk 32/300 | F7: =('2017'!F7*Faktor!$B$6)+'2017'!F7 -> 4.23904
A8: Begynderstykke | B8: =('2017'!B8*Faktor!$B$6)+'2017'!B8 -> 5.61469 | E8: Profildæk 32/250 | F8: =('2017'!F8*Faktor!$B$6)+'2017'!F8 -> 4.23904
A9: Vertikalstander 300 | B9: =('2017'!B9*Faktor!$B$6)+'2017'!B9 -> 33.73909 | E9: Profildæk 32/200 | F9: =('2017'!F9*Faktor!$B$6)+'2017'!F9 -> 4.23904
A10: Vertikalstander 200 | B10: =('2017'!B10*Faktor!$B$6)+'2017'!B10 -> 22.49952 | E10: Profildæk 32/150 | F10: =('2017'!F10*Faktor!$B$6)+'2017'!F10 -> 2.10933
A11: Vertikalstander 150 | B11: =('2017'!B11*Faktor!$B$6)+'2017'!B11 -> 16.88483 | E11: Profildæk 32/125 | F11: =('2017'!F11*Faktor!$B$6)+'2017'!F11 -> 2.10933
A12: Vertikalstander 100 | B12: =('2017'!B12*Faktor!$B$6)+'2017'!B12 -> 11.23957 | E12: Profildæk 32/74 | F12: =('2017'!F12*Faktor!$B$6)+'2017'!F12 -> 2.10933
E13: Stigedæk | F13: =('2017'!F13*Faktor!$B$6)+'2017'!F13 -> 8.33542
A14: Horisontalrør 300 | B14: =('2017'!B14*Faktor!$B$6)+'2017'!B14 -> 5.01348 | E14: Profildæk 70/300 | F14: =('2017'!F14*Faktor!$B$6)+'2017'!F14 -> 4.91158
A15: Horisontalrør 250 | B15: =('2017'!B15*Faktor!$B$6)+'2017'!B15 -> 5.01348 | E15: Profildæk 70/250 | F15: =('2017'!F15*Faktor!$B$6)+'2017'!F15 -> 4.06581
A16: Horisontalrør 200 | B16: =('2017'!B16*Faktor!$B$6)+'2017'!B16 -> 5.01348 | E16: Profildæk 70/200 | F16: =('2017'!F16*Faktor!$B$6)+'2017'!F16 -> 3.2608
A17: Horisontalrør 150 | B17: =('2017'!B17*Faktor!$B$6)+'2017'!B17 -> 5.01348 | E17: Profildæk 70/150 | F17: =('2017'!F17*Faktor!$B$6)+'2017'!F17 -> 2.43541
A18: Horisontalrør 125 | B18: =('2017'!B18*Faktor!$B$6)+'2017'!B18 -> 5.01348 | E18: Profildæk 70/125 | F18: =('2017'!F18*Faktor!$B$6)+'2017'!F18 -> 2.04819
A19: Horisontalrør 113 | B19: =('2017'!B19*Faktor!$B$6)+'2017'!B19 -> 5.01348 | E19: Profildæk 70/70 | F19: =('2017'!F19*Faktor!$B$6)+'2017'!F19 -> 1.16166
A20: Horisontalrør 74 | B20: =('2017'!B20*Faktor!$B$6)+'2017'!B20 -> 5.01348
A21: U-profil 300 | B21: =('2017'!B21*Faktor!$B$6)+'2017'!B21 -> 5.01348 | E21: Stilladsrør 1M | F21: =('2017'!F21*Faktor!$B$6)+'2017'!F21 -> 4.55493
A22: U-profil 250 | B22: =('2017'!B22*Faktor!$B$6)+'2017'!B22 -> 5.01348 | E22: Stilladsrør 2M | F22: =('2017'!F22*Faktor!$B$6)+'2017'!F22 -> 9.10986
A23: U-profil 200 | B23: =('2017'!B23*Faktor!$B$6)+'2017'!B23 -> 5.01348 | E23: Stilladsrør 3M | F23: =('2017'!F23*Faktor!$B$6)+'2017'!F23 -> 13.66479
A24: U-profil 150 | B24: =('2017'!B24*Faktor!$B$6)+'2017'!B24 -> 5.01348 | E24: Stilladsrør 4M | F24: =('2017'!F24*Faktor!$B$6)+'2017'!F24 -> 18.21972
A25: U-profil 113 | B25: =('2017'!B25*Faktor!$B$6)+'2017'!B25 -> 5.01348 | E25: Stilladsrør 5M | F25: =('2017'!F25*Faktor!$B$6)+'2017'!F25 -> 22.77465
A26: Løftesikring 113 | B26: =('2017'!B26*Faktor!$B$6)+'2017'!B26 -> 2.8399187 | E26: Stilladsrør 6M | F26: =('2017'!F26*Faktor!$B$6)+'2017'!F26 -> 27.32958
A27: Løftesikring 150 | B27: =('2017'!B27*Faktor!$B$6)+'2017'!B27 -> 2.8399187
A28: Diagonal 200/300 | B28: =('2017'!B28*Faktor!$B$6)+'2017'!B28 -> 6.0121
A29: Diagonal 200/250 | B29: =('2017'!B29*Faktor!$B$6)+'2017'!B29 -> 6.0121
A30: Diagonal 200/200 | B30: =('2017'!B30*Faktor!$B$6)+'2017'!B30 -> 6.0121 | E30: Klodæk 300/70 | F30: =('2017'!F30*Faktor!$B$6)+'2017'!F30 -> 4.91158
A31: Diagonal 200/150 | B31: =('2017'!B31*Faktor!$B$6)+'2017'!B31 -> 6.0121 | E31: Klodæk 250/70 | F31: =('2017'!F31*Faktor!$B$6)+'2017'!F31 -> 4.06581
A32: Diagonal 200/113 | B32: =('2017'!B32*Faktor!$B$6)+'2017'!B32 -> 6.0121 | E32: Alutrappe 2m | F32: =('2017'!F32*Faktor!$B$6)+'2017'!F32 -> 42.44135
A33: Fodspark 300 | B33: =('2017'!B33*Faktor!$B$6)+'2017'!B33 -> 5.1969 | E33: Gelænder til trappe | F33: =('2017'!F33*Faktor!$B$6)+'2017'!F33 -> 10.61798
A34: Fodspark 250 | B34: =('2017'!B34*Faktor!$B$6)+'2017'!B34 -> 5.1969
A35: Fodspark 200 | B35: =('2017'!B35*Faktor!$B$6)+'2017'!B35 -> 5.1969
A36: Fodspark 150 | B36: =('2017'!B36*Faktor!$B$6)+'2017'!B36 -> 5.1969 | E36: Koblinger fast | F36: =('2017'!F36*Faktor!$B$6)+'2017'!F36 -> 3.30156
A37: Fodspark 125 | B37: =('2017'!B37*Faktor!$B$6)+'2017'!B37 -> 5.1969 | E37: Koblinger dreje | F37: =('2017'!F37*Faktor!$B$6)+'2017'!F37 -> 3.30156
E38: Koblinger SK | F38: =('2017'!F38*Faktor!$B$6)+'2017'!F38 -> 3.30156
E39: Koblinger Kipfinger | F39: =('2017'!F39*Faktor!$B$6)+'2017'!F39 -> 3.30156
A40: Bøjleanker | B40: =('2017'!B40*Faktor!$B$6)+'2017'!B40 -> 6.78654 | E40: Koblinger singel | F40: =('2017'!F40*Faktor!$B$6)+'2017'!F40 -> 3.30156
...

Sheet 2019
A1: MODEX 2019
A2: Sted | E2: Dato
A3: Opgave | E3: Mont.
A4: Kunde | E4: Demo.
A5: Sag nr. | E5: Montør
B6: Pris | C6: Antal | D6: I alt | F6: Pris | G6: Antal | H6: I alt
A7: Spindelfod | B7: =('2018'!B7*Faktor!$B$7)+'2018'!B7 -> 2.2510321 | E7: Profildæk 32/300 | F7: =('2018'!F7*Faktor!$B$7)+'2018'!F7 -> 4.3153427
A8: Begynderstykke | B8: =('2018'!B8*Faktor!$B$7)+'2018'!B8 -> 5.7157544 | E8: Profildæk 32/250 | F8: =('2018'!F8*Faktor!$B$7)+'2018'!F8 -> 4.3153427
A9: Vertikalstander 300 | B9: =('2018'!B9*Faktor!$B$7)+'2018'!B9 -> 34.346394 | E9: Profildæk 32/200 | F9: =('2018'!F9*Faktor!$B$7)+'2018'!F9 -> 4.3153427
A10: Vertikalstander 200 | B10: =('2018'!B10*Faktor!$B$7)+'2018'!B10 -> 22.904511 | E10: Profildæk 32/150 | F10: =('2018'!F10*Faktor!$B$7)+'2018'!F10 -> 2.1472979
A11: Vertikalstander 150 | B11: =('2018'!B11*Faktor!$B$7)+'2018'!B11 -> 17.188757 | E11: Profildæk 32/125 | F11: =('2018'!F11*Faktor!$B$7)+'2018'!F11 -> 2.1472979
A12: Vertikalstander 100 | B12: =('2018'!B12*Faktor!$B$7)+'2018'!B12 -> 11.441882 | E12: Profildæk 32/74 | F12: =('2018'!F12*Faktor!$B$7)+'2018'!F12 -> 2.1472979
E13: Stigedæk | F13: =('2018'!F13*Faktor!$B$7)+'2018'!F13 -> 8.4854576
A14: Horisontalrør 300 | B14: =('2018'!B14*Faktor!$B$7)+'2018'!B14 -> 5.1037226 | E14: Profildæk 70/300 | F14: =('2018'!F14*Faktor!$B$7)+'2018'!F14 -> 4.9999884
A15: Horisontalrør 250 | B15: =('2018'!B15*Faktor!$B$7)+'2018'!B15 -> 5.1037226 | E15: Profildæk 70/250 | F15: =('2018'!F15*Faktor!$B$7)+'2018'!F15 -> 4.1389946
A16: Horisontalrør 200 | B16: =('2018'!B16*Faktor!$B$7)+'2018'!B16 -> 5.1037226 | E16: Profildæk 70/200 | F16: =('2018'!F16*Faktor!$B$7)+'2018'!F16 -> 3.3194944
A17: Horisontalrør 150 | B17: =('2018'!B17*Faktor!$B$7)+'2018'!B17 -> 5.1037226 | E17: Profildæk 70/150 | F17: =('2018'!F17*Faktor!$B$7)+'2018'!F17 -> 2.4792474
A18: Horisontalrør 125 | B18: =('2018'!B18*Faktor!$B$7)+'2018'!B18 -> 5.1037226 | E18: Profildæk 70/125 | F18: =('2018'!F18*Faktor!$B$7)+'2018'!F18 -> 2.0850574
A19: Horisontalrør 113 | B19: =('2018'!B19*Faktor!$B$7)+'2018'!B19 -> 5.1037226 | E19: Profildæk 70/70 | F19: =('2018'!F19*Faktor!$B$7)+'2018'!F19 -> 1.1825699
A20: Horisontalrør 74 | B20: =('2018'!B20*Faktor!$B$7)+'2018'!B20 -> 5.1037226
A21: U-profil 300 | B21: =('2018'!B21*Faktor!$B$7)+'2018'!B21 -> 5.1037226 | E21: Stilladsrør 1M | F21: =('2018'!F21*Faktor!$B$7)+'2018'!F21 -> 4.6369187
A22: U-profil 250 | B22: =('2018'!B22*Faktor!$B$7)+'2018'!B22 -> 5.1037226 | E22: Stilladsrør 2M | F22: =('2018'!F22*Faktor!$B$7)+'2018'!F22 -> 9.2738375
A23: U-profil 200 | B23: =('2018'!B23*Faktor!$B$7)+'2018'!B23 -> 5.1037226 | E23: Stilladsrør 3M | F23: =('2018'!F23*Faktor!$B$7)+'2018'!F23 -> 13.910756
A24: U-profil 150 | B24: =('2018'!B24*Faktor!$B$7)+'2018'!B24 -> 5.1037226 | E24: Stilladsrør 4M | F24: =('2018'!F24*Faktor!$B$7)+'2018'!F24 -> 18.547675
A25: U-profil 113 | B25: =('2018'!B25*Faktor!$B$7)+'2018'!B25 -> 5.1037226 | E25: Stilladsrør 5M | F25: =('2018'!F25*Faktor!$B$7)+'2018'!F25 -> 23.184594
A26: Løftesikring 113 | B26: =('2018'!B26*Faktor!$B$7)+'2018'!B26 -> 2.8910373 | E26: Stilladsrør 6M | F26: =('2018'!F26*Faktor!$B$7)+'2018'!F26 -> 27.821512
A27: Løftesikring 150 | B27: =('2018'!B27*Faktor!$B$7)+'2018'!B27 -> 2.8910373
A28: Diagonal 200/300 | B28: =('2018'!B28*Faktor!$B$7)+'2018'!B28 -> 6.1203178
A29: Diagonal 200/250 | B29: =('2018'!B29*Faktor!$B$7)+'2018'!B29 -> 6.1203178
A30: Diagonal 200/200 | B30: =('2018'!B30*Faktor!$B$7)+'2018'!B30 -> 6.1203178 | E30: Klodæk 300/70 | F30: =('2018'!F30*Faktor!$B$7)+'2018'!F30 -> 4.9999884
A31: Diagonal 200/150 | B31: =('2018'!B31*Faktor!$B$7)+'2018'!B31 -> 6.1203178 | E31: Klodæk 250/70 | F31: =('2018'!F31*Faktor!$B$7)+'2018'!F31 -> 4.1389946
A32: Diagonal 200/113 | B32: =('2018'!B32*Faktor!$B$7)+'2018'!B32 -> 6.1203178 | E32: Alutrappe 2m | F32: =('2018'!F32*Faktor!$B$7)+'2018'!F32 -> 43.205294
A33: Fodspark 300 | B33: =('2018'!B33*Faktor!$B$7)+'2018'!B33 -> 5.2904442 | E33: Gelænder til trappe | F33: =('2018'!F33*Faktor!$B$7)+'2018'!F33 -> 10.809104
A34: Fodspark 250 | B34: =('2018'!B34*Faktor!$B$7)+'2018'!B34 -> 5.2904442
A35: Fodspark 200 | B35: =('2018'!B35*Faktor!$B$7)+'2018'!B35 -> 5.2904442
A36: Fodspark 150 | B36: =('2018'!B36*Faktor!$B$7)+'2018'!B36 -> 5.2904442 | E36: Koblinger fast | F36: =('2018'!F36*Faktor!$B$7)+'2018'!F36 -> 3.3609881
A37: Fodspark 125 | B37: =('2018'!B37*Faktor!$B$7)+'2018'!B37 -> 5.2904442 | E37: Koblinger dreje | F37: =('2018'!F37*Faktor!$B$7)+'2018'!F37 -> 3.3609881
E38: Koblinger SK | F38: =('2018'!F38*Faktor!$B$7)+'2018'!F38 -> 3.3609881
E39: Koblinger Kipfinger | F39: =('2018'!F39*Faktor!$B$7)+'2018'!F39 -> 3.3609881
A40: Bøjleanker | B40: =('2018'!B40*Faktor!$B$7)+'2018'!B40 -> 6.9086977 | E40: Koblinger singel | F40: =('2018'!F40*Faktor!$B$7)+'2018'!F40 -> 3.3609881
...

Sheet 2020
A1: MODEX 2021
A2: Sted | E2: Dato
A3: Opgave | E3: Mont.
A4: Kunde | E4: Demo.
A5: Sag nr.
A6: Montør
B7: Pris | C7: Antal | D7: I alt | F7: Pris | G7: Antal | H7: I alt
A8: Spindelfod | B8: 2.36 | E8: Profildæk 32/300 | F8: 4.21
A9: Begynderstykke | B9: =('2019'!B8*Faktor!$B$8)+'2019'!B8 -> 5.8357853 | E9: Profildæk 32/250 | F9: 4.21
A10: Vertikalstander 300 | B10: 35.91 | E10: Profildæk 32/200 | F10: 4.21
A11: Vertikalstander 200 | B11: 23.94 | E11: Profildæk 32/150 | F11: 2.25
A12: Vertikalstander 150 | B12: 17.97 | E12: Profildæk 32/125 | F12: 2.25
A13: Vertikalstander 100 | B13: 11.97 | E13: Profildæk 32/74 | F13: 2.25
E14: Stigedæk | F14: 8.87
A15: Horisontalrør 300 | B15: 5.34 | E15: Profildæk 70/300 | F15: 5.6
A16: Horisontalrør 250 | B16: 5.34 | E16: Profildæk 70/250 | F16: 5.6
A17: Horisontalrør 200 | B17: 5.34 | E17: Profildæk 70/200 | F17: 5.6
A18: Horisontalrør 150 | B18: 5.34 | E18: Profildæk 70/150 | F18: 5.6
A19: Horisontalrør 125 | B19: 5.34 | E19: Profildæk 70/125 | F19: 5.6
A20: Horisontalrør 113 | B20: 5.34 | E20: Profildæk 70/70 | F20: 5.6
A21: Horisontalrør 74 | B21: 5.34 | E21: Stilladsrør 1M | F21: 4.85
E22: Stilladsrør 2M | F22: 9.7
E23: Stilladsrør 3M | F23: 14.43
E24: Stilladsrør 4M | F24: 19.4
A25: U-profil 150 | B25: 5.34 | E25: Stilladsrør 5M | F25: 24.25
A26: U-profil 113 | B26: 5.34 | E26: Stilladsrør 6M | F26: 28.98
A27: Løftesikring 113 | B27: 3.51 | E27: Klodæk 300/70 | F27: 5.6
A28: Løftesikring 150 | B28: 3.51 | E28: Klodæk 250/70 | F28: 5.6
A29: Diagonal 200/300 | B29: 6.4 | E29: Alutrappe 2m | F29: 45.17
A30: Diagonal 200/250 | B30: 6.4 | E30: Gelænder til trappe | F30: 11.3
A31: Diagonal 200/200 | B31: 6.4 | E31: Koblinger fast | F31: 3.51
A32: Diagonal 200/150 | B32: 6.4 | E32: Koblinger dreje | F32: 3.51
A33: Diagonal 200/113 | B33: 6.4 | E33: Koblinger SK | F33: 3.51
A34: Fodspark 300 | B34: 5.53 | E34: Koblinger Kipfinger | F34: 3.51
A35: Fodspark 250 | B35: 5.53 | E35: Koblinger singel | F35: 3.51
A36: Fodspark 200 | B36: 5.53 | E36: Koblinger samler | F36: 3.51
... A38: Fodspark 125 | B38: 5.53 | E38: Røranker | F38: 9.04
E39: Strø / trykudligner | F39: 1.56
E40: Alu. Drager pr. m. | F40: 15.05
E41: Grønne skilte | F41: 5
...

Sheet 2021
A1: MODEX 2021
A2: Sted | E2: Dato
A3: Opgave | E3: Mont.
A4: Kunde | E4: Demo.
A5: Sag nr.
A6: Montør
B7: Pris | C7: Antal | D7: I alt | F7: Pris | G7: Antal | H7: I alt
A8: Spindelfod | B8: 2.36 | E8: Profildæk 32/300 | F8: 4.21
A9: Begynderstykke | B9: 5.84 | E9: Profildæk 32/250 | F9: 4.21
A10: Vertikalstander 300 | B10: 35.91 | E10: Profildæk 32/200 | F10: 4.21
A11: Vertikalstander 200 | B11: 23.94 | E11: Profildæk 32/150 | F11: 2.25
A12: Vertikalstander 150 | B12: 17.97 | E12: Profildæk 32/125 | F12: 2.25
A13: Vertikalstander 100 | B13: 11.97 | E13: Profildæk 32/74 | F13: 2.25
E14: Stigedæk | F14: 8.87
A15: Horisontalrør 300 | B15: 5.34 | E15: Profildæk 70/300 | F15: 5.6
A16: Horisontalrør 250 | B16: 5.34 | E16: Profildæk 70/250 | F16: 5.6
A17: Horisontalrør 200 | B17: 5.34 | E17: Profildæk 70/200 | F17: 5.6
A18: Horisontalrør 150 | B18: 5.34 | E18: Profildæk 70/150 | F18: 5.6
A19: Horisontalrør 125 | B19: 5.34 | E19: Profildæk 70/125 | F19: 5.6
A20: Horisontalrør 113 | B20: 5.34 | E20: Profildæk 70/70 | F20: 5.6
A21: Horisontalrør 74 | B21: 5.34 | E21: Stilladsrør 1M | F21: 4.85
E22: Stilladsrør 2M | F22: 9.7
E23: Stilladsrør 3M | F23: 14.43
E24: Stilladsrør 4M | F24: 19.4
A25: U-profil 150 | B25: 5.34 | E25: Stilladsrør 5M | F25: 24.25
A26: U-profil 113 | B26: 5.34 | E26: Stilladsrør 6M | F26: 28.98
A27: Løftesikring 113 | B27: 3.51 | E27: Klodæk 300/70 | F27: 5.6
A28: Løftesikring 150 | B28: 3.51 | E28: Klodæk 250/70 | F28: 5.6
A29: Diagonal 200/300 | B29: 6.4 | E29: Alutrappe 2m | F29: 45.17
A30: Diagonal 200/250 | B30: 6.4 | E30: Gelænder til trappe | F30: 11.3
A31: Diagonal 200/200 | B31: 6.4 | E31: Koblinger fast | F31: 3.51
A32: Diagonal 200/150 | B32: 6.4 | E32: Koblinger dreje | F32: 3.51
A33: Diagonal 200/113 | B33: 6.4 | E33: Koblinger SK | F33: 3.51
A34: Fodspark 300 | B34: 5.53 | E34: Koblinger Kipfinger | F34: 3.51
A35: Fodspark 250 | B35: 5.53 | E35: Koblinger singel | F35: 3.51
A36: Fodspark 200 | B36: 5.53 | E36: Koblinger samler | F36: 3.51
... A38: Fodspark 125 | B38: 5.53 | E38: Røranker | F38: 9.04
E39: Strø / trykudligner | F39: 1.56
E40: Alu. Drager pr. m. | F40: 15.05
E41: Grønne skilte | F41: 5
...

Sheet 2022
A1: MODEX 2023
A2: Sted | E2: Dato
A3: Opgave | E3: Mont.
A4: Kunde | E4: Demo.
A5: Sag nr.
A6: Montør
B7: Pris | C7: Antal | D7: I alt | F7: Pris | G7: Antal | H7: I alt
A8: Spindelfod | B8: 2.5 | E8: Profildæk 32/300 | F8: 7.81
A9: Begynderstykke | B9: 3.91 | E9: Profildæk 32/250 | F9: 5.85
A10: Vertikalstander 300 | B10: 23.43 | E10: Profildæk 32/200 | F10: 5.85
A11: Vertikalstander 200 | B11: 15.62 | E11: Profildæk 32/150 | F11: 3.9
A12: Vertikalstander 150 | B12: 11.72 | E12: Profildæk 32/125 | F12: 3.9
A13: Vertikalstander 100 | B13: 7.81 | E13: Profildæk 32/74 | F13: 3.9
E14: Profildæk 70/300 | F14: 15.61
A15: Horisontalrør 300 | B15: 8.78 | E15: Profildæk 70/250 | F15: 11.71
A16: Horisontalrør 250 | B16: 5.85 | E16: Profildæk 70/200 | F16: 11.71
A17: Horisontalrør 200 | B17: 5.85 | E17: Profildæk 70/150 | F17: 7.81
A18: Horisontalrør 150 | B18: 4.88 | E18: Profildæk 70/125 | F18: 7.81
A19: Horisontalrør 125 | B19: 4.88 | E19: Profildæk 70/70 | F19: 7.81
A20: Horisontalrør 113 | B20: 4.88 | E20: Stilladsrør 1M | F20: 5.15
A21: Horisontalrør 74 | B21: 4.88 | E21: Stilladsrør 2M | F21: =F20*2 -> 10.3
E22: Stilladsrør 3M | F22: =F20*3 -> 15.45
E23: Stilladsrør 4M | F23: =F20*4 -> 20.6
E24: Stilladsrør 5M | F24: =F20*5 -> 25.75
A25: U-profil 150 | B25: 4.88 | E25: Stilladsrør 6M | F25: =F20*6 -> 30.9
A26: U-profil 113 | B26: 4.88 | E26: Stilladsrør 6M alu | F26: =3.73*6 -> 22.38
A27: Løftesikring 113 | B27: 3.73 | E27: Klodæk 300/70 | F27: 15.61
A28: Løftesikring 150 | B28: 3.73 | E28: Klodæk 250/70 | F28: 11.71
A29: Diagonal 200/300 | B29: 8.78 | E29: Alutrappe 2m | F29: 47.96
A30: Diagonal 200/250 | B30: 8.78 | E30: Gelænder til trappe | F30: 12.51
A31: Diagonal 200/200 | B31: 8.78 | E31: Koblinger fast | F31: 3.73
A32: Diagonal 200/150 | B32: 8.78 | E32: Koblinger dreje | F32: 3.73
A33: Diagonal 200/113 | B33: 8.78 | E33: Koblinger SK | F33: 3.73
A34: Fodspark 300 | B34: 8.78 | E34: Koblinger Kipfinger | F34: 3.73
A35: Fodspark 250 | B35: 7.81 | E35: Koblinger singel | F35: 3.73
A36: Fodspark 200 | B36: 7.81 | E36: Koblinger samler | F36: 3.73
A37: Fodspark 150 | B37: 5.85 | E37: Bøjleanker | F37: 13.66
A38: Fodspark 125 | B38: 5.85 | E38: Røranker alu | F38: 13.66
E39: Røranker stål | F39: 17.56
A40: Stigedæk 3m | B40: 19.51 | E40: Strø / trykudligner | F40: 1.66
...

Sheet 2023
A1: MODEX 2023
A2: Sted | E2: Dato
A3: Opgave | E3: Mont.
A4: Kunde | E4: Demo.
A5: Sag nr.
A6: Montør
B7: Pris | C7: Antal | D7: I alt | F7: Pris | G7: Antal | H7: I alt
A8: Spindelfod | B8: 2.5 | E8: Profildæk 32/300 | F8: 7.81
A9: Begynderstykke | B9: 3.91 | E9: Profildæk 32/250 | F9: 5.85
A10: Vertikalstander 300 | B10: 23.43 | E10: Profildæk 32/200 | F10: 5.85
A11: Vertikalstander 200 | B11: 15.62 | E11: Profildæk 32/150 | F11: 3.9
A12: Vertikalstander 150 | B12: 11.72 | E12: Profildæk 32/125 | F12: 3.9
A13: Vertikalstander 100 | B13: 7.81 | E13: Profildæk 32/74 | F13: 3.9
E14: Profildæk 70/300 | F14: 15.61
A15: Horisontalrør 300 | B15: 8.78 | E15: Profildæk 70/250 | F15: 11.71
A16: Horisontalrør 250 | B16: 5.85 | E16: Profildæk 70/200 | F16: 11.71
A17: Horisontalrør 200 | B17: 5.85 | E17: Profildæk 70/150 | F17: 7.81
A18: Horisontalrør 150 | B18: 4.88 | E18: Profildæk 70/125 | F18: 7.81
A19: Horisontalrør 125 | B19: 4.88 | E19: Profildæk 70/70 | F19: 7.81
A20: Horisontalrør 113 | B20: 4.88 | E20: Stilladsrør 1M | F20: 5.15
A21: Horisontalrør 74 | B21: 4.88 | E21: Stilladsrør 2M | F21: =F20*2 -> 10.3
E22: Stilladsrør 3M | F22: =F20*3 -> 15.45
E23: Stilladsrør 4M | F23: =F20*4 -> 20.6
E24: Stilladsrør 5M | F24: =F20*5 -> 25.75
A25: U-profil 150 | B25: 4.88 | E25: Stilladsrør 6M | F25: =F20*6 -> 30.9
A26: U-profil 113 | B26: 4.88 | E26: Stilladsrør 6M alu | F26: =3.73*6 -> 22.38
A27: Løftesikring 113 | B27: 3.73 | E27: Klodæk 300/70 | F27: 15.61
A28: Løftesikring 150 | B28: 3.73 | E28: Klodæk 250/70 | F28: 11.71
A29: Diagonal 200/300 | B29: 8.78 | E29: Alutrappe 2m | F29: 47.96
A30: Diagonal 200/250 | B30: 8.78 | E30: Gelænder til trappe | F30: 12.51
A31: Diagonal 200/200 | B31: 8.78 | E31: Koblinger fast | F31: 3.73
A32: Diagonal 200/150 | B32: 8.78 | E32: Koblinger dreje | F32: 3.73
A33: Diagonal 200/113 | B33: 8.78 | E33: Koblinger SK | F33: 3.73
A34: Fodspark 300 | B34: 8.78 | E34: Koblinger Kipfinger | F34: 3.73
A35: Fodspark 250 | B35: 7.81 | E35: Koblinger singel | F35: 3.73
A36: Fodspark 200 | B36: 7.81 | E36: Koblinger samler | F36: 3.73
A37: Fodspark 150 | B37: 5.85 | E37: Bøjleanker | F37: 13.66
A38: Fodspark 125 | B38: 5.85 | E38: Røranker alu | F38: 13.66
E39: Røranker stål | F39: 17.56
A40: Stigedæk 3m | B40: 19.51 | E40: Strø / trykudligner | F40: 1.66
...

Sheet 2025
A1: MODEX 2025
A2: Sted | E2: Dato
A3: Opgave | E3: Mont.
A4: Kunde | E4: Demo.
A5: Sag nr.
A6: Montør
B7: Pris | C7: Antal | D7: I alt | F7: Pris | G7: Antal | H7: I alt
A8: Spindelfod | B8: 2.68 | E8: Profildæk 32/300 | F8: 15.66
A9: Begynderstykke | B9: 4.18 | E9: Profildæk 32/250 | F9: 10.44
A10: Vertikalstander 300 | B10: 25.05 | E10: Profildæk 32/200 | F10: 8.35
A11: Vertikalstander 200 | B11: 16.7 | E11: Profildæk 32/150 | F11: 6.26
A12: Vertikalstander 150 | B12: 12.53 | E12: Profildæk 32/125 | F12: 6.26
A13: Vertikalstander 100 | B13: 8.35 | E13: Profildæk 32/74 | F13: 6.26
E14: Profildæk 70/300 | F14: 16.71
A15: Horisontalrør 300 | B15: 9.4 | E15: Profildæk 70/250 | F15: 12.53
A16: Horisontalrør 250 | B16: 6.26 | E16: Profildæk 70/200 | F16: 12.53
A17: Horisontalrør 200 | B17: 6.25 | E17: Profildæk 70/150 | F17: 8.35
A18: Horisontalrør 150 | B18: 5.23 | E18: Profildæk 70/125 | F18: 8.35
A19: Horisontalrør 125 | B19: 5.22 | E19: Profildæk 70/70 | F19: 8.35
A20: Horisontalrør 113 | B20: 5.22 | E20: Stilladsrør 1M | F20: 5.51
A21: Horisontalrør 74 | B21: 5.22 | E21: Stilladsrør 2M | F21: 11.02
E22: Stilladsrør 3M | F22: 16.53
E23: Stilladsrør 4M | F23: 22.04
E24: Stilladsrør 5M | F24: 27.55
A25: U-profil 150 | B25: 5.22 | E25: Stilladsrør 6M | F25: 33.06
A26: U-profil 113 | B26: 5.22 | E26: Stilladsrør 6M alu | F26: 23.94
A27: Løftesikring 113 | B27: 3.99 | E27: Klodæk 300/70 | F27: 16.71
A28: Løftesikring 150 | B28: 3.99 | E28: Klodæk 250/70 | F28: 17.53
A29: Diagonal 200/300 | B29: 9.4 | E29: Alutrappe 2m | F29: 51.33
A30: Diagonal 200/250 | B30: 9.4 | E30: Gelænder til trappe | F30: 13.39
A31: Diagonal 200/200 | B31: 9.4 | E31: Koblinger fast | F31: 3.99
A32: Diagonal 200/150 | B32: 9.4 | E32: Koblinger dreje | F32: 3.99
A33: Diagonal 200/113 | B33: 9.4 | E33: Koblinger SK | F33: 3.99
A34: Fodspark 300 | B34: 9.4 | E34: Koblinger Kipfinger | F34: 3.99
A35: Fodspark 250 | B35: 8.35 | E35: Koblinger singel | F35: 3.99
A36: Fodspark 200 | B36: 8.35 | E36: Koblinger samler | F36: 3.99
... A38: Fodspark 125 | B38: 6.26 | E38: Røranker alu | F38: 14.62
E39: Røranker stål | F39: 18.79
A40: Stigedæk 3m | B40: 20.88 | E40: Strø / trykudligner | F40: 1.77
A41: Stigedæk 2,5m | B41: 16.71 | E41: Alu. Drager pr. m. | F41: 17.12
...
